Workbook

Sheet 1.Início
B2: CALCULADORA DE SALVA NAVAL MULTI-DOMÍNIO v1.5
B3: Modelo heterogêneo multi-domínio · Parâmetros por tipo de unidade · Engajamento simultâneo ou sequencial
B4: Versão 1.5 — Maio/2026 · Elaborada por Alberto Ferreira Filho · Baseado em Johns–Pilnick–Hughes (2001) e Hausken–Moxnes (2026)
B6: FLUXO DE USO (7 PASSOS)
B7: Passo 1 → 2.Forças | C7: Inventário Azul e Vermelha (tipo, domínio, quantidade)
B8: Passo 2 → 3.Parâm_Azul | C8: β, ζ, σ, τ, ρ, δ, ς por unidade Azul × cada alvo Vermelha
B9: Passo 3 → 4.Parâm_Verm | C9: Idem para unidades Vermelha
B10: Passo 4 → 5.Mira | C10: Matrizes γ (ofensiva) e θ (defensiva) por par de tipos
B11: Passo 5 → 6.Cibernético | C11: Sub-tipos y_σ, y_ρ, y_δ, y_def e parâmetros da sigmoide Φ
B12: Passo 6 → 7.Config | C12: Modo de engajamento, admissibilidade, tempo característico
B13: Passo 7 → 9.Simulação | C13: Veja propagação automática; resumo em 10.Resultados
B15: MODOS DE ENGAJAMENTO
B16: Simultâneo | C16: Caso base [Hughes, 1995]: ambos os lados disparam usando forças do início da salva.
B17: Azul ataca primeiro | C17: [Armstrong, 2014] sequencial: Azul dispara → Vermelha sofre → Vermelha sobrevivente retalha.
B18: Vermelha ataca primeiro | C18: [Armstrong, 2014] sequencial: Vermelha dispara → Azul sofre → Azul sobrevivente retalha.
B20: LEGENDA DE CORES
C21: Célula EDITÁVEL (texto azul)
C22: Célula calculada
C23: Resultado / OK
C24: Alerta / restrição violada
C25: Dados AZUL
C26: Dados VERMELHA
B28: OBSERVAÇÃO IMPORTANTE
B29: A aba 8.MotorCalc contém os cálculos intermediários e pode ser ocultada (clique direito na aba → Ocultar). Não é necessário editá-la. Os resultados aparecem nas abas 9.Simulação e 10.Resultados.

Sheet 2.Forças
B2: INVENTÁRIO INICIAL DE FORÇAS
B4: 🛡️ LADO AZUL | F4: ⚔️ LADO VERMELHA
B5: Tipo de Unidade | C5: Dom. | D5: Qtd. inicial | F5: Tipo de Unidade | G5: Dom. | H5: Qtd. inicial
B6: Fragata Cl. Tamandaré | C6: s | D6: 2 | F6: Destróier (atacante) | G6: s | H6: 2
B7: Fragata Cl. Niterói mod | C7: s | D7: 2 | F7: Fragata (atacante) | G7: s | H7: 2
B8: Submarino Cl. Riachuelo | C8: u | D8: 1 | F8: Aeronave ataque c/ASM | G8: a | H8: 6
B9: Aeronave P-3AM | C9: a | D9: 3 | F9: Aeronave escolta caça | G9: a | H9: 3
B10: UAV de patrulha | C10: a | D10: 2 | F10: UAV ISR | G10: a | H10: 2
B11: FPSO (alvo fixo) | C11: c | D11: 6
B12: Bateria MANSUP costeira | C12: c | D12: 2

Sheet 3.Parâmetros_Azul
B2: PARÂMETROS DE COMBATE — LADO AZUL
B3: β = potência ofensiva · ζ = potência defensiva · σ⁰,τ⁰,ρ⁰,δ⁰ ∈ [0,1] = scouting, treinamento, distração, alerta · ς = staying power
B5: Unidade ATACANTE | C5: Alvo (inimigo) | D5: β | E5: ζ | F5: σ⁰ | G5: τ⁰ | H5: ρ⁰ | I5: δ⁰ | J5: ς
B6: ↗ Fragata Cl. Tamandaré [s] atacando →
B7: Fragata Cl. Tamandaré | C7: Destróier (atacante) [s] | D7: 2 | E7: 1.5 | F7: 0.85 | G7: 0.9 | H7: 0.8 | I7: 0.85 | J7: 3
B8: Fragata Cl. Tamandaré | C8: Fragata (atacante) [s] | D8: 2 | E8: 1.5 | F8: 0.85 | G8: 0.9 | H8: 0.8 | I8: 0.85 | J8: 3
B9: Fragata Cl. Tamandaré | C9: Aeronave ataque c/ASM [a] | D9: 1.2 | E9: 0.05 | F9: 0.75 | G9: 0.85 | H9: 0.7 | I9: 0.8 | J9: 1
B10: Fragata Cl. Tamandaré | C10: Aeronave escolta caça [a] | D10: 1.2 | E10: 0.05 | F10: 0.75 | G10: 0.85 | H10: 0.7 | I10: 0.8 | J10: 1
B11: Fragata Cl. Tamandaré | C11: UAV ISR [a] | D11: 1.2 | E11: 0.05 | F11: 0.75 | G11: 0.85 | H11: 0.7 | I11: 0.8 | J11: 1
B13: ↗ Fragata Cl. Niterói mod [s] atacando →
B14: Fragata Cl. Niterói mod | C14: Destróier (atacante) [s] | D14: 2 | E14: 1.5 | F14: 0.85 | G14: 0.9 | H14: 0.8 | I14: 0.85 | J14: 3
B15: Fragata Cl. Niterói mod | C15: Fragata (atacante) [s] | D15: 2 | E15: 1.5 | F15: 0.85 | G15: 0.9 | H15: 0.8 | I15: 0.85 | J15: 3
B16: Fragata Cl. Niterói mod | C16: Aeronave ataque c/ASM [a] | D16: 1.2 | E16: 0.05 | F16: 0.75 | G16: 0.85 | H16: 0.7 | I16: 0.8 | J16: 1
B17: Fragata Cl. Niterói mod | C17: Aeronave escolta caça [a] | D17: 1.2 | E17: 0.05 | F17: 0.75 | G17: 0.85 | H17: 0.7 | I17: 0.8 | J17: 1
B18: Fragata Cl. Niterói mod | C18: UAV ISR [a] | D18: 1.2 | E18: 0.05 | F18: 0.75 | G18: 0.85 | H18: 0.7 | I18: 0.8 | J18: 1
B20: ↗ Submarino Cl. Riachuelo [u] atacando →
B21: Submarino Cl. Riachuelo | C21: Destróier (atacante) [s] | D21: 2.5 | E21: 1 | F21: 0.8 | G21: 0.9 | H21: 0.65 | I21: 0.8 | J21: 3
B22: Submarino Cl. Riachuelo | C22: Fragata (atacante) [s] | D22: 2.5 | E22: 1 | F22: 0.8 | G22: 0.9 | H22: 0.65 | I22: 0.8 | J22: 3
B23: Submarino Cl. Riachuelo | C23: Aeronave ataque c/ASM [a] | D23: 0.3 | E23: 0.02 | F23: 0.4 | G23: 0.7 | H23: 0.5 | I23: 0.7 | J23: 1
B24: Submarino Cl. Riachuelo | C24: Aeronave escolta caça [a] | D24: 0.3 | E24: 0.02 | F24: 0.4 | G24: 0.7 | H24: 0.5 | I24: 0.7 | J24: 1
B25: Submarino Cl. Riachuelo | C25: UAV ISR [a] | D25: 0.3 | E25: 0.02 | F25: 0.4 | G25: 0.7 | H25: 0.5 | I25: 0.7 | J25: 1
B27: ↗ Aeronave P-3AM [a] atacando →
B28: Aeronave P-3AM | C28: Destróier (atacante) [s] | D28: 2.2 | E28: 1.5 | F28: 0.85 | G28: 0.85 | H28: 0.7 | I28: 0.8 | J28: 3
B29: Aeronave P-3AM | C29: Fragata (atacante) [s] | D29: 2.2 | E29: 1.5 | F29: 0.85 | G29: 0.85 | H29: 0.7 | I29: 0.8 | J29: 3
B30: Aeronave P-3AM | C30: Aeronave ataque c/ASM [a] | D30: 1.5 | E30: 1.2 | F30: 0.8 | G30: 0.85 | H30: 0.75 | I30: 0.8 | J30: 1
B31: Aeronave P-3AM | C31: Aeronave escolta caça [a] | D31: 1.5 | E31: 1.2 | F31: 0.8 | G31: 0.85 | H31: 0.75 | I31: 0.8 | J31: 1
B32: Aeronave P-3AM | C32: UAV ISR [a] | D32: 1.5 | E32: 1.2 | F32: 0.8 | G32: 0.85 | H32: 0.75 | I32: 0.8 | J32: 1
B34: ↗ UAV de patrulha [a] atacando →
B35: UAV de patrulha | C35: Destróier (atacante) [s] | D35: 2.2 | E35: 1.5 | F35: 0.85 | G35: 0.85 | H35: 0.7 | I35: 0.8 | J35: 3
B36: UAV de patrulha | C36: Fragata (atacante) [s] | D36: 2.2 | E36: 1.5 | F36: 0.85 | G36: 0.85 | H36: 0.7 | I36: 0.8 | J36: 3
B37: UAV de patrulha | C37: Aeronave ataque c/ASM [a] | D37: 1.5 | E37: 1.2 | F37: 0.8 | G37: 0.85 | H37: 0.75 | I37: 0.8 | J37: 1
B38: UAV de patrulha | C38: Aeronave escolta caça [a] | D38: 1.5 | E38: 1.2 | F38: 0.8 | G38: 0.85 | H38: 0.75 | I38: 0.8 | J38: 1
B39: UAV de patrulha | C39: UAV ISR [a] | D39: 1.5 | E39: 1.2 | F39: 0.8 | G39: 0.85 | H39: 0.75 | I39: 0.8 | J39: 1
B41: ↗ FPSO (alvo fixo) [c] atacando →
B42: FPSO (alvo fixo) | C42: Destróier (atacante) [s] | D42: 2 | E42: 1 | F42: 0.75 | G42: 0.8 | H42: 0.7 | I42: 0.8 | J42: 3
B43: FPSO (alvo fixo) | C43: Fragata (atacante) [s] | D43: 2 | E43: 1 | F43: 0.75 | G43: 0.8 | H43: 0.7 | I43: 0.8 | J43: 3
B44: FPSO (alvo fixo) | C44: Aeronave ataque c/ASM [a] | D44: 1 | E44: 0.1 | F44: 0.7 | G44: 0.8 | H44: 0.65 | I44: 0.75 | J44: 1
B45: FPSO (alvo fixo) | C45: Aeronave escolta caça [a] | D45: 1 | E45: 0.1 | F45: 0.7 | G45: 0.8 | H45: 0.65 | I45: 0.75 | J45: 1
B46: FPSO (alvo fixo) | C46: UAV ISR [a] | D46: 1 | E46: 0.1 | F46: 0.7 | G46: 0.8 | H46: 0.65 | I46: 0.75 | J46: 1
B48: ↗ Bateria MANSUP costeira [c] atacando →
...

Sheet 4.Parâmetros_Verm
B2: PARÂMETROS DE COMBATE — LADO VERMELHA
B3: β = potência ofensiva · ζ = potência defensiva · σ⁰,τ⁰,ρ⁰,δ⁰ ∈ [0,1] = scouting, treinamento, distração, alerta · ς = staying power
B5: Unidade ATACANTE | C5: Alvo (inimigo) | D5: β | E5: ζ | F5: σ⁰ | G5: τ⁰ | H5: ρ⁰ | I5: δ⁰ | J5: ς
B6: ↗ Destróier (atacante) [s] atacando →
B7: Destróier (atacante) | C7: Fragata Cl. Tamandaré [s] | D7: 2 | E7: 1.5 | F7: 0.85 | G7: 0.9 | H7: 0.8 | I7: 0.85 | J7: 3
B8: Destróier (atacante) | C8: Fragata Cl. Niterói mod [s] | D8: 2 | E8: 1.5 | F8: 0.85 | G8: 0.9 | H8: 0.8 | I8: 0.85 | J8: 3
B9: Destróier (atacante) | C9: Submarino Cl. Riachuelo [u] | D9: 0.6 | E9: 0.1 | F9: 0.55 | G9: 0.85 | H9: 0.7 | I9: 0.8 | J9: 5
B10: Destróier (atacante) | C10: Aeronave P-3AM [a] | D10: 1.2 | E10: 0.05 | F10: 0.75 | G10: 0.85 | H10: 0.7 | I10: 0.8 | J10: 1
B11: Destróier (atacante) | C11: UAV de patrulha [a] | D11: 1.2 | E11: 0.05 | F11: 0.75 | G11: 0.85 | H11: 0.7 | I11: 0.8 | J11: 1
B12: Destróier (atacante) | C12: FPSO (alvo fixo) [c] | D12: 1.8 | E12: 0.2 | F12: 0.8 | G12: 0.85 | H12: 0.75 | I12: 0.8 | J12: 4
B13: Destróier (atacante) | C13: Bateria MANSUP costeira [c] | D13: 1.8 | E13: 0.2 | F13: 0.8 | G13: 0.85 | H13: 0.75 | I13: 0.8 | J13: 4
B15: ↗ Fragata (atacante) [s] atacando →
B16: Fragata (atacante) | C16: Fragata Cl. Tamandaré [s] | D16: 2 | E16: 1.5 | F16: 0.85 | G16: 0.9 | H16: 0.8 | I16: 0.85 | J16: 3
B17: Fragata (atacante) | C17: Fragata Cl. Niterói mod [s] | D17: 2 | E17: 1.5 | F17: 0.85 | G17: 0.9 | H17: 0.8 | I17: 0.85 | J17: 3
B18: Fragata (atacante) | C18: Submarino Cl. Riachuelo [u] | D18: 0.6 | E18: 0.1 | F18: 0.55 | G18: 0.85 | H18: 0.7 | I18: 0.8 | J18: 5
B19: Fragata (atacante) | C19: Aeronave P-3AM [a] | D19: 1.2 | E19: 0.05 | F19: 0.75 | G19: 0.85 | H19: 0.7 | I19: 0.8 | J19: 1
B20: Fragata (atacante) | C20: UAV de patrulha [a] | D20: 1.2 | E20: 0.05 | F20: 0.75 | G20: 0.85 | H20: 0.7 | I20: 0.8 | J20: 1
B21: Fragata (atacante) | C21: FPSO (alvo fixo) [c] | D21: 1.8 | E21: 0.2 | F21: 0.8 | G21: 0.85 | H21: 0.75 | I21: 0.8 | J21: 4
B22: Fragata (atacante) | C22: Bateria MANSUP costeira [c] | D22: 1.8 | E22: 0.2 | F22: 0.8 | G22: 0.85 | H22: 0.75 | I22: 0.8 | J22: 4
B24: ↗ Aeronave ataque c/ASM [a] atacando →
B25: Aeronave ataque c/ASM | C25: Fragata Cl. Tamandaré [s] | D25: 2.2 | E25: 1.5 | F25: 0.85 | G25: 0.85 | H25: 0.7 | I25: 0.8 | J25: 3
B26: Aeronave ataque c/ASM | C26: Fragata Cl. Niterói mod [s] | D26: 2.2 | E26: 1.5 | F26: 0.85 | G26: 0.85 | H26: 0.7 | I26: 0.8 | J26: 3
B27: Aeronave ataque c/ASM | C27: Submarino Cl. Riachuelo [u] | D27: 0.8 | E27: 0.05 | F27: 0.55 | G27: 0.8 | H27: 0.75 | I27: 0.8 | J27: 5
B28: Aeronave ataque c/ASM | C28: Aeronave P-3AM [a] | D28: 1.5 | E28: 1.2 | F28: 0.8 | G28: 0.85 | H28: 0.75 | I28: 0.8 | J28: 1
B29: Aeronave ataque c/ASM | C29: UAV de patrulha [a] | D29: 1.5 | E29: 1.2 | F29: 0.8 | G29: 0.85 | H29: 0.75 | I29: 0.8 | J29: 1
B30: Aeronave ataque c/ASM | C30: FPSO (alvo fixo) [c] | D30: 2 | E30: 0.15 | F30: 0.85 | G30: 0.85 | H30: 0.75 | I30: 0.8 | J30: 4
B31: Aeronave ataque c/ASM | C31: Bateria MANSUP costeira [c] | D31: 2 | E31: 0.15 | F31: 0.85 | G31: 0.85 | H31: 0.75 | I31: 0.8 | J31: 4
B33: ↗ Aeronave escolta caça [a] atacando →
B34: Aeronave escolta caça | C34: Fragata Cl. Tamandaré [s] | D34: 2.2 | E34: 1.5 | F34: 0.85 | G34: 0.85 | H34: 0.7 | I34: 0.8 | J34: 3
B35: Aeronave escolta caça | C35: Fragata Cl. Niterói mod [s] | D35: 2.2 | E35: 1.5 | F35: 0.85 | G35: 0.85 | H35: 0.7 | I35: 0.8 | J35: 3
B36: Aeronave escolta caça | C36: Submarino Cl. Riachuelo [u] | D36: 0.8 | E36: 0.05 | F36: 0.55 | G36: 0.8 | H36: 0.75 | I36: 0.8 | J36: 5
B37: Aeronave escolta caça | C37: Aeronave P-3AM [a] | D37: 1.5 | E37: 1.2 | F37: 0.8 | G37: 0.85 | H37: 0.75 | I37: 0.8 | J37: 1
B38: Aeronave escolta caça | C38: UAV de patrulha [a] | D38: 1.5 | E38: 1.2 | F38: 0.8 | G38: 0.85 | H38: 0.75 | I38: 0.8 | J38: 1
B39: Aeronave escolta caça | C39: FPSO (alvo fixo) [c] | D39: 2 | E39: 0.15 | F39: 0.85 | G39: 0.85 | H39: 0.75 | I39: 0.8 | J39: 4
B40: Aeronave escolta caça | C40: Bateria MANSUP costeira [c] | D40: 2 | E40: 0.15 | F40: 0.85 | G40: 0.85 | H40: 0.75 | I40: 0.8 | J40: 4
B42: ↗ UAV ISR [a] atacando →
B43: UAV ISR | C43: Fragata Cl. Tamandaré [s] | D43: 2.2 | E43: 1.5 | F43: 0.85 | G43: 0.85 | H43: 0.7 | I43: 0.8 | J43: 3
B44: UAV ISR | C44: Fragata Cl. Niterói mod [s] | D44: 2.2 | E44: 1.5 | F44: 0.85 | G44: 0.85 | H44: 0.7 | I44: 0.8 | J44: 3
B45: UAV ISR | C45: Submarino Cl. Riachuelo [u] | D45: 0.8 | E45: 0.05 | F45: 0.55 | G45: 0.8 | H45: 0.75 | I45: 0.8 | J45: 5
B46: UAV ISR | C46: Aeronave P-3AM [a] | D46: 1.5 | E46: 1.2 | F46: 0.8 | G46: 0.85 | H46: 0.75 | I46: 0.8 | J46: 1
...

Sheet 5.Mira
B2: MATRIZES DE MIRA — γ (ofensiva) e θ (defensiva)
B4: γ AZUL → VERMELHA (fração ofensiva — pode exceder 1 para s/u)
B5: ↓Atacante / Alvo→ | C5: Destróier (atacant | D5: Fragata (atacante) | E5: Aeronave ataque c/ | F5: Aeronave escolta c | G5: UAV ISR | H5: Σ (limite)
B6: Fragata Cl. Tamandaré | C6: 0.25 | D6: 0.25 | E6: 0.25 | F6: 0.25 | G6: 0.25 | H6: =C6+D6+E6+F6+G6 -> 1.25
B7: Fragata Cl. Niterói mod | C7: 0.25 | D7: 0.25 | E7: 0.25 | F7: 0.25 | G7: 0.25 | H7: =C7+D7+E7+F7+G7 -> 1.25
B8: Submarino Cl. Riachuelo | C8: 0.4 | D8: 0.4 | E8: 0.05 | F8: 0.05 | G8: 0.05 | H8: =C8+D8+E8+F8+G8 -> 0.95
B9: Aeronave P-3AM | C9: 0.225 | D9: 0.225 | E9: 0.125 | F9: 0.125 | G9: 0.125 | H9: =C9+D9+E9+F9+G9 -> 0.825
B10: UAV de patrulha | C10: 0.225 | D10: 0.225 | E10: 0.125 | F10: 0.125 | G10: 0.125 | H10: =C10+D10+E10+F10+G10 -> 0.825
B11: FPSO (alvo fixo) | C11: 0.3 | D11: 0.3 | E11: 0.125 | F11: 0.125 | G11: 0.125 | H11: =C11+D11+E11+F11+G11 -> 0.975
B12: Bateria MANSUP costeira | C12: 0.3 | D12: 0.3 | E12: 0.125 | F12: 0.125 | G12: 0.125 | H12: =C12+D12+E12+F12+G12 -> 0.975
B15: γ VERMELHA → AZUL (fração ofensiva — pode exceder 1 para s/u)
B16: ↓Atacante / Alvo→ | C16: Fragata Cl. Tamand | D16: Fragata Cl. Niteró | E16: Submarino Cl. Riac | F16: Aeronave P-3AM | G16: UAV de patrulha | H16: FPSO (alvo fixo) | I16: Bateria MANSUP cos | J16: Σ (limite)
B17: Destróier (atacante) | C17: 0.25 | D17: 0.25 | E17: 0.15 | F17: 0.25 | G17: 0.25 | H17: 0.15 | I17: 0.15 | J17: =C17+D17+E17+F17+G17+H17+I17 -> 1.45
B18: Fragata (atacante) | C18: 0.25 | D18: 0.25 | E18: 0.15 | F18: 0.25 | G18: 0.25 | H18: 0.15 | I18: 0.15 | J18: =C18+D18+E18+F18+G18+H18+I18 -> 1.45
B19: Aeronave ataque c/ASM | C19: 0.225 | D19: 0.225 | E19: 0.05 | F19: 0.125 | G19: 0.125 | H19: 0.1 | I19: 0.1 | J19: =C19+D19+E19+F19+G19+H19+I19 -> 0.95
B20: Aeronave escolta caça | C20: 0.225 | D20: 0.225 | E20: 0.05 | F20: 0.125 | G20: 0.125 | H20: 0.1 | I20: 0.1 | J20: =C20+D20+E20+F20+G20+H20+I20 -> 0.95
B21: UAV ISR | C21: 0.225 | D21: 0.225 | E21: 0.05 | F21: 0.125 | G21: 0.125 | H21: 0.1 | I21: 0.1 | J21: =C21+D21+E21+F21+G21+H21+I21 -> 0.95
B24: θ AZUL defendendo de VERMELHA (fração defensiva — sempre ≤ 1)
B25: ↓Atacante / Alvo→ | C25: Destróier (atacant | D25: Fragata (atacante) | E25: Aeronave ataque c/ | F25: Aeronave escolta c | G25: UAV ISR | H25: Σ (≤1)
B26: Fragata Cl. Tamandaré | C26: 0.25 | D26: 0.25 | E26: 0.15 | F26: 0.15 | G26: 0.15 | H26: =C26+D26+E26+F26+G26 -> 0.95
B27: Fragata Cl. Niterói mod | C27: 0.25 | D27: 0.25 | E27: 0.15 | F27: 0.15 | G27: 0.15 | H27: =C27+D27+E27+F27+G27 -> 0.95
B28: Submarino Cl. Riachuelo | C28: 0.05 | D28: 0.05 | E28: 0 | F28: 0 | G28: 0 | H28: =C28+D28+E28+F28+G28 -> 0.1
B29: Aeronave P-3AM | C29: 0.05 | D29: 0.05 | E29: 0.25 | F29: 0.25 | G29: 0.25 | H29: =C29+D29+E29+F29+G29 -> 0.85
B30: UAV de patrulha | C30: 0.05 | D30: 0.05 | E30: 0.25 | F30: 0.25 | G30: 0.25 | H30: =C30+D30+E30+F30+G30 -> 0.85
B31: FPSO (alvo fixo) | C31: 0.1 | D31: 0.1 | E31: 0.15 | F31: 0.15 | G31: 0.15 | H31: =C31+D31+E31+F31+G31 -> 0.65
B32: Bateria MANSUP costeira | C32: 0.1 | D32: 0.1 | E32: 0.15 | F32: 0.15 | G32: 0.15 | H32: =C32+D32+E32+F32+G32 -> 0.65
B35: θ VERMELHA defendendo de AZUL (fração defensiva — sempre ≤ 1)
B36: ↓Atacante / Alvo→ | C36: Fragata Cl. Tamand | D36: Fragata Cl. Niteró | E36: Submarino Cl. Riac | F36: Aeronave P-3AM | G36: UAV de patrulha | H36: FPSO (alvo fixo) | I36: Bateria MANSUP cos | J36: Σ (≤1)
B37: Destróier (atacante) | C37: 0.25 | D37: 0.25 | E37: 0.1 | F37: 0.15 | G37: 0.15 | H37: 0.05 | I37: 0.05 | J37: =C37+D37+E37+F37+G37+H37+I37 -> 1
B38: Fragata (atacante) | C38: 0.25 | D38: 0.25 | E38: 0.1 | F38: 0.15 | G38: 0.15 | H38: 0.05 | I38: 0.05 | J38: =C38+D38+E38+F38+G38+H38+I38 -> 1
B39: Aeronave ataque c/ASM | C39: 0.05 | D39: 0.05 | E39: 0.025 | F39: 0.25 | G39: 0.25 | H39: 0.05 | I39: 0.05 | J39: =C39+D39+E39+F39+G39+H39+I39 -> 0.725
B40: Aeronave escolta caça | C40: 0.05 | D40: 0.05 | E40: 0.025 | F40: 0.25 | G40: 0.25 | H40: 0.05 | I40: 0.05 | J40: =C40+D40+E40+F40+G40+H40+I40 -> 0.725
B41: UAV ISR | C41: 0.05 | D41: 0.05 | E41: 0.025 | F41: 0.25 | G41: 0.25 | H41: 0.05 | I41: 0.05 | J41: =C41+D41+E41+F41+G41+H41+I41 -> 0.725

Sheet 6.Cibernético
B2: DOMÍNIO CIBERNÉTICO-ELETROMAGNÉTICO
B3: Sub-tipos cibernéticos e cálculo dos fatores Φᵟ, Φᵖ, Φᵟ. Submarinos imunes (Φ ≡ 1).
B5: SUB-TIPOS E PESOS POR CANAL
B6: Sub-tipo | C6: Função | D6: w(σ) | E6: w(ρ) | F6: w(δ) | G6: Azul | H6: Vermelha
B7: y_σ | C7: Jamming/SIGINT | D7: 0.7 | E7: 0.1 | F7: 0.1 | G7: 6 | H7: 7
B8: y_ρ | C8: Spoofing/decoy | D8: 0.1 | E8: 0.7 | F8: 0.1 | G8: 5 | H8: 6
B9: y_δ | C9: Ataque a CMS/C² | D9: 0.1 | E9: 0.1 | F9: 0.7 | G9: 4 | H9: 6
B10: y_def | C10: COMSEC/hardening | D10: 0.5 | E10: 0.5 | F10: 0.5 | G10: 8 | H10: 6
B13: PARÂMETROS Φᵖ = 1 / [1 + (Rᵖ/r₀ᵖ)^kᵖ]
B14: Canal | C14: r₀ | D14: k | E14: R | F14: Φ Azul | G14: Φ Verm.
B15: Canal σ | C15: 1 | D15: 2 | E15: =SUMPRODUCT(D7:D10,H7:H10)/MAX(0.0001,SUMPRODUCT(D7:D10,G7:G10)) -> 1 | F15: =1/(1+(E15/MAX(0.0001,C15))^D15) -> 0.5 | G15: =1/(1+((1/MAX(0.0001,E15))/MAX(0.0001,C15))^D15) -> 0.5
B16: Canal ρ | C16: 1 | D16: 2 | E16: =SUMPRODUCT(E7:E10,H7:H10)/MAX(0.0001,SUMPRODUCT(E7:E10,G7:G10)) -> 1 | F16: =1/(1+(E16/MAX(0.0001,C16))^D16) -> 0.5 | G16: =1/(1+((1/MAX(0.0001,E16))/MAX(0.0001,C16))^D16) -> 0.5
B17: Canal δ | C17: 1 | D17: 2 | E17: =SUMPRODUCT(F7:F10,H7:H10)/MAX(0.0001,SUMPRODUCT(F7:F10,G7:G10)) -> 1.0759494 | F17: =1/(1+(E17/MAX(0.0001,C17))^D17) -> 0.46346354 | G17: =1/(1+((1/MAX(0.0001,E17))/MAX(0.0001,C17))^D17) -> 0.53653646
B21: Φ FINAIS PARA SIMULAÇÃO
B22: Lado | C22: Φᵟ(σ) | D22: Φᵖ(ρ) | E22: Φᵟ(δ)
B23: Azul (não-sub.) | C23: =F15 -> 0.5 | D23: =F16 -> 0.5 | E23: =F17 -> 0.46346354
B24: Verm. (não-sub.) | C24: =G15 -> 0.5 | D24: =G16 -> 0.5 | E24: =G17 -> 0.53653646
B25: Submarino — IMUNE | C25: =1 -> 1 | D25: =1 -> 1 | E25: =1 -> 1

Sheet 7.Config
B2: CONFIGURAÇÃO DO ENGAJAMENTO
B4: MODO DE ENGAJAMENTO
B5: Modo: | C5: Simultâneo | D5: Selecione o modo do menu suspenso
B8: MATRIZ DE ADMISSIBILIDADE 𝟙⁽ᵈ',ᵈ⁾
B9: d' \ d | C9: s | D9: u | E9: a | F9: c
B10: s | C10: 1 | D10: 1 | E10: 1 | F10: 1
B11: u | C11: 1 | D11: 1 | E11: 0.5 | F11: 0.5
B12: a | C12: 1 | D12: 1 | E12: 1 | F12: 1
B13: c | C13: 1 | D13: 0.5 | E13: 1 | F13: 1
B16: TEMPO CARACTERÍSTICO POR DOMÍNIO (min/salva)
B17: a | C17: 1
B18: s | C18: 10
B19: c | C19: 10
B20: u | C20: 30
B21: y | C21: 5

Sheet 8.MotorCalc
A1: MOTOR DE CÁLCULO INTERMEDIÁRIO (auxiliar — pode ocultar)
A2: Esta aba contém os termos individuais de ataque e defesa por par (atacante, alvo). A aba 9.Simulação consome estes valores.
A4: Grupo | B4: Alvo / unidade | C4: S1 | D4: S2 | E4: S3 | F4: S4 | G4: S5 | H4: S6 | I4: S7 | J4: S8 | K4: S9 | L4: S10
A5: Az_inc_sim | B5: Fragata Cl. Tamandaré | C5: =('7.Config'!$C$10*'4.Parâmetros_Verm'!$D$7*'4.Parâmetros_Verm'!$F$7*'4.Parâmetros_Verm'!$G$7*'4.Parâmetros_Verm'!$H$7*'5.Mira'!$C$17*'6.Cibernético'!$C$24*'6.Cibernético'!$D$23*'9.Simulação'!$K$7)+('7.Config'!$C$10*'4.Parâmetros_Verm'!$D$16*'4.Parâmetros_Verm'!$F$16*'4.Parâmetros_Verm'!$G$16*'4.Parâmetros_Verm'!$H$16*'5.Mira'!$C$18*'6.Cibernético'!$C$24*'6.Cibernético'!$D$23*'9.Simulação'!$L$7)+('7.Config'!$C$12*'4.Parâmetros_Verm'!$D$25*'4.Parâmetros_Verm'!$F$25*'4.Parâmetros_Verm'!$G$25*'4.Parâmetros_Verm'!$H$25*'5.Mira'!$C$19*'6.Cibernético'!$C$24*'6.Cibernético'!$D$23*'9.Simulação'!$M$7)+('7.Config'!$C$12*'4.Parâmetros_Verm'!$D$34*'4.Parâmetros_Verm'!$F$34*'4.Parâmetros_Verm'!$G$34*'4.Parâmetros_Verm'!$H$34*'5.Mira'!$C$20*'6.Cibernético'!$C$24*'6.Cibernético'!$D$23*'9.Simulação'!$N$7)+('7.Config'!$C$12*'4.Parâmetros_Verm'!$D$43*'4.Parâmetros_Verm'!$F$43*'4.Parâmetros_Verm'!$G$43*'4.Parâmetros_Verm'!$H$43*'5.Mira'!$C$21*'6.Cibernético'!$C$24*'6.Cibernético'!$D$23*'9.Simulação'!$O$7) -> 0.99445219 | D5: =('7.Config'!$C$10*'4.Parâmetros_Verm'!$D$7*'4.Parâmetros_Verm'!$F$7*'4.Parâmetros_Verm'!$G$7*'4.Parâmetros_Verm'!$H$7*'5.Mira'!$C$17*'6.Cibernético'!$C$24*'6.Cibernético'!$D$23*'9.Simulação'!$K$8)+('7.Config'!$C$10*'4.Parâmetros_Verm'!$D$16*'4.Parâmetros_Verm'!$F$16*'4.Parâmetros_Verm'!$G$16*'4.Parâmetros_Verm'!$H$16*'5.Mira'!$C$18*'6.Cibernético'!$C$24*'6.Cibernético'!$D$23*'9.Simulação'!$L$8)+('7.Config'!$C$12*'4.Parâmetros_Verm'!$D$25*'4.Parâmetros_Verm'!$F$25*'4.Parâmetros_Verm'!$G$25*'4.Parâmetros_Verm'!$H$25*'5.Mira'!$C$19*'6.Cibernético'!$C$24*'6.Cibernético'!$D$23*'9.Simulação'!$M$8)+('7.Config'!$C$12*'4.Parâmetros_Verm'!$D$34*'4.Parâmetros_Verm'!$F$34*'4.Parâmetros_Verm'!$G$34*'4.Parâmetros_Verm'!$H$34*'5.Mira'!$C$20*'6.Cibernético'!$C$24*'6.Cibernético'!$D$23*'9.Simulação'!$N$8)+('7.Config'!$C$12*'4.Parâmetros_Verm'!$D$43*'4.Parâmetros_Verm'!$F$43*'4.Parâmetros_Verm'!$G$43*'4.Parâmetros_Verm'!$H$43*'5.Mira'!$C$21*'6.Cibernético'!$C$24*'6.Cibernético'!$D$23*'9.Simulação'!$O$8) -> 0.99083924 | E5: =('7.Config'!$C$10*'4.Parâmetros_Verm'!$D$7*'4.Parâmetros_Verm'!$F$7*'4.Parâmetros_Verm'!$G$7*'4.Parâmetros_Verm'!$H$7*'5.Mira'!$C$17*'6.Cibernético'!$C$24*'6.Cibernético'!$D$23*'9.Simulação'!$K$9)+('7.Config'!$C$10*'4.Parâmetros_Verm'!$D$16*'4.Parâmetros_Verm'!$F$16*'4.Parâmetros_Verm'!$G$16*'4.Parâmetros_Verm'!$H$16*'5.Mira'!$C$18*'6.Cibernético'!$C$24*'6.Cibernético'!$D$23*'9.Simulação'!$L$9)+('7.Config'!$C$12*'4.Parâmetros_Verm'!$D$25*'4.Parâmetros_Verm'!$F$25*'4.Parâmetros_Verm'!$G$25*'4.Parâmetros_Verm'!$H$25*'5.Mira'!$C$19*'6.Cibernético'!$C$24*'6.Cibernético'!$D$23*'9.Simulação'!$M$9)+('7.Config'!$C$12*'4.Parâmetros_Verm'!$D$34*'4.Parâmetros_Verm'!$F$34*'4.Parâmetros_Verm'!$G$34*'4.Parâmetros_Verm'!$H$34*'5.Mira'!$C$20*'6.Cibernético'!$C$24*'6.Cibernético'!$D$23*'9.Simulação'!$N$9)+('7.Config'!$C$12*'4.Parâmetros_Verm'!$D$43*'4.Parâmetros_Verm'!$F$43*'4.Parâmetros_Verm'!$G$43*'4.Parâmetros_Verm'!$H$43*'5.Mira'!$C$21*'6.Cibernético'!$C$24*'6.Cibernético'!$D$23*'9.Simulação'!$O$9) -> 0.98720287 | F5: =('7.Config'!$C$10*'4.Parâmetros_Verm'!$D$7*'4.Parâmetros_Verm'!$F$7*'4.Parâmetros_Verm'!$G$7*'4.Parâmetros_Verm'!$H$7*'5.Mira'!$C$17*'6.Cibernético'!$C$24*'6.Cibernético'!$D$23*'9.Simulação'!$K$10)+('7.Config'!$C$10*'4.Parâmetros_Verm'!$D$16*'4.Parâmetros_Verm'!$F$16*'4.Parâmetros_Verm'!$G$16*'4.Parâmetros_Verm'!$H$16*'5.Mira'!$C$18*'6.Cibernético'!$C$24*'6.Cibernético'!$D$23*'9.Simulação'!$L$10)+('7.Config'!$C$12*'4.Parâmetros_Verm'!$D$25*'4.Parâmetros_Verm'!$F$25*'4.Parâmetros_Verm'!$G$25*'4.Parâmetros_Verm'!$H$25*'5.Mira'!$C$19*'6.Cibernético'!$C$24*'6.Cibernético'!$D$23*'9.Simulação'!$M$10)+('7.Config'!$C$12*'4.Parâmetros_Verm'!$D$34*'4.Parâmetros_Verm'!$F$34*'4.Parâmetros_Verm'!$G$34*'4.Parâmetros_Verm'!$H$34*'5.Mira'!$C$20*'6.Cibernético'!$C$24*'6.Cibernético'!$D$23*'9.Simulação'!$N$10)+('7.Config'!$C$12*'4.Parâmetros_Verm'!$D$43*'4.Parâmetros_Verm'!$F$43*'4.Parâmetros_Verm'!$G$43*'4.Parâmetros_Verm'!$H$43*'5.Mira'!$C$21*'6.Cibernético'!$C$24*'6.Cibernético'!$D$23*'9.Simulação'!$O$10) -> 0.98354281 | G5: =('7.Config'!$C$10*'4.Parâmetros_Verm'!$D$7*'4.Parâmetros_Verm'!$F$7*'4.Parâmetros_Verm'!$G$7*'4.Parâmetros_Verm'!$H$7*'5.Mira'!$C$17*'6.Cibernético'!$C$24*'6.Cibernético'!$D$23*'9.Simulação'!$K$11)+('7.Config'!$C$10*'4.Parâmetros_Verm'!$D$16*'4.Parâmetros_Verm'!$F$16*'4.Parâmetros_Verm'!$G$16*'4.Parâmetros_Verm'!$H$16*'5.Mira'!$C$18*'6.Cibernético'!$C$24*'6.Cibernético'!$D$23*'9.Simulação'!$L$11)+('7.Config'!$C$12*'4.Parâmetros_Verm'!$D$25*'4.Parâmetros_Verm'!$F$25*'4.Parâmetros_Verm'!$G$25*'4.Parâmetros_Verm'!$H$25*'5.Mira'!$C$19*'6.Cibernético'!$C$24*'6.Cibernético'!$D$23*'9.Simulação'!$M$11)+('7.Config'!$C$12*'4.Parâmetros_Verm'!$D$34*'4.Parâmetros_Verm'!$F$34*'4.Parâmetros_Verm'!$G$34*'4.Parâmetros_Verm'!$H$34*'5.Mira'!$C$20*'6.Cibernético'!$C$24*'6.Cibernético'!$D$23*'9.Simulação'!$N$11)+('7.Config'!$C$12*'4.Parâmetros_Verm'!$D$43*'4.Parâmetros_Verm'!$F$43*'4.Parâmetros_Verm'!$G$43*'4.Parâmetros_Verm'!$H$43*'5.Mira'!$C$21*'6.Cibernético'!$C$24*'6.Cibernético'!$D$23*'9.Simulação'!$O$11) -> 0.97985877 | H5: =('7.Config'!$C$10*'4.Parâmetros_Verm'!$D$7*'4.Parâmetros_Verm'!$F$7*'4.Parâmetros_Verm'!$G$7*'4.Parâmetros_Verm'!$H$7*'5.Mira'!$C$17*'6.Cibernético'!$C$24*'6.Cibernético'!$D$23*'9.Simulação'!$K$12)+('7.Config'!$C$10*'4.Parâmetros_Verm'!$D$16*'4.Parâmetros_Verm'!$F$16*'4.Parâmetros_Verm'!$G$16*'4.Parâmetros_Verm'!$H$16*'5.Mira'!$C$18*'6.Cibernético'!$C$24*'6.Cibernético'!$D$23*'9.Simulação'!$L$12)+('7.Config'!$C$12*'4.Parâmetros_Verm'!$D$25*'4.Parâmetros_Verm'!$F$25*'4.Parâmetros_Verm'!$G$25*'4.Parâmetros_Verm'!$H$25*'5.Mira'!$C$19*'6.Cibernético'!$C$24*'6.Cibernético'!$D$23*'9.Simulação'!$M$12)+('7.Config'!$C$12*'4.Parâmetros_Verm'!$D$34*'4.Parâmetros_Verm'!$F$34*'4.Parâmetros_Verm'!$G$34*'4.Parâmetros_Verm'!$H$34*'5.Mira'!$C$20*'6.Cibernético'!$C$24*'6.Cibernético'!$D$23*'9.Simulação'!$N$12)+('7.Config'!$C$12*'4.Parâmetros_Verm'!$D$43*'4.Parâmetros_Verm'!$F$43*'4.Parâmetros_Verm'!$G$43*'4.Parâmetros_Verm'!$H$43*'5.Mira'!$C$21*'6.Cibernético'!$C$24*'6.Cibernético'!$D$23*'9.Simulação'!$O$12) -> 0.97615047 | I5: =('7.Config'!$C$10*'4.Parâmetros_Verm'!$D$7*'4.Parâmetros_Verm'!$F$7*'4.Parâmetros_Verm'!$G$7*'4.Parâmetros_Verm'!$H$7*'5.Mira'!$C$17*'6.Cibernético'!$C$24*'6.Cibernético'!$D$23*'9.Simulação'!$K$13)+('7.Config'!$C$10*'4.Parâmetros_Verm'!$D$16*'4.Parâmetros_Verm'!$F$16*'4.Parâmetros_Verm'!$G$16*'4.Parâmetros_Verm'!$H$16*'5.Mira'!$C$18*'6.Cibernético'!$C$24*'6.Cibernético'!$D$23*'9.Simulação'!$L$13)+('7.Config'!$C$12*'4.Parâmetros_Verm'!$D$25*'4.Parâmetros_Verm'!$F$25*'4.Parâmetros_Verm'!$G$25*'4.Parâmetros_Verm'!$H$25*'5.Mira'!$C$19*'6.Cibernético'!$C$24*'6.Cibernético'!$D$23*'9.Simulação'!$M$13)+('7.Config'!$C$12*'4.Parâmetros_Verm'!$D$34*'4.Parâmetros_Verm'!$F$34*'4.Parâmetros_Verm'!$G$34*'4.Parâmetros_Verm'!$H$34*'5.Mira'!$C$20*'6.Cibernético'!$C$24*'6.Cibernético'!$D$23*'9.Simulação'!$N$13)+('7.Config'!$C$12*'4.Parâmetros_Verm'!$D$43*'4.Parâmetros_Verm'!$F$43*'4.Parâmetros_Verm'!$G$43*'4.Parâmetros_Verm'!$H$43*'5.Mira'!$C$21*'6.Cibernético'!$C$24*'6.Cibernético'!$D$23*'9.Simulação'!$O$13) -> 0.97241764 | J5: =('7.Config'!$C$10*'4.Parâmetros_Verm'!$D$7*'4.Parâmetros_Verm'!$F$7*'4.Parâmetros_Verm'!$G$7*'4.Parâmetros_Verm'!$H$7*'5.Mira'!$C$17*'6.Cibernético'!$C$24*'6.Cibernético'!$D$23*'9.Simulação'!$K$14)+('7.Config'!$C$10*'4.Parâmetros_Verm'!$D$16*'4.Parâmetros_Verm'!$F$16*'4.Parâmetros_Verm'!$G$16*'4.Parâmetros_Verm'!$H$16*'5.Mira'!$C$18*'6.Cibernético'!$C$24*'6.Cibernético'!$D$23*'9.Simulação'!$L$14)+('7.Config'!$C$12*'4.Parâmetros_Verm'!$D$25*'4.Parâmetros_Verm'!$F$25*'4.Parâmetros_Verm'!$G$25*'4.Parâmetros_Verm'!$H$25*'5.Mira'!$C$19*'6.Cibernético'!$C$24*'6.Cibernético'!$D$23*'9.Simulação'!$M$14)+('7.Config'!$C$12*'4.Parâmetros_Verm'!$D$34*'4.Parâmetros_Verm'!$F$34*'4.Parâmetros_Verm'!$G$34*'4.Parâmetros_Verm'!$H$34*'5.Mira'!$C$20*'6.Cibernético'!$C$24*'6.Cibernético'!$D$23*'9.Simulação'!$N$14)+('7.Config'!$C$12*'4.Parâmetros_Verm'!$D$43*'4.Parâmetros_Verm'!$F$43*'4.Parâmetros_Verm'!$G$43*'4.Parâmetros_Verm'!$H$43*'5.Mira'!$C$21*'6.Cibernético'!$C$24*'6.Cibernético'!$D$23*'9.Simulação'!$O$14) -> 0.96866001 | K5: =('7.Config'!$C$10*'4.Parâmetros_Verm'!$D$7*'4.Parâmetros_Verm'!$F$7*'4.Parâmetros_Verm'!$G$7*'4.Parâmetros_Verm'!$H$7*'5.Mira'!$C$17*'6.Cibernético'!$C$24*'6.Cibernético'!$D$23*'9.Simulação'!$K$15)+('7.Config'!$C$10*'4.Parâmetros_Verm'!$D$16*'4.Parâmetros_Verm'!$F$16*'4.Parâmetros_Verm'!$G$16*'4.Parâmetros_Verm'!$H$16*'5.Mira'!$C$18*'6.Cibernético'!$C$24*'6.Cibernético'!$D$23*'9.Simulação'!$L$15)+('7.Config'!$C$12*'4.Parâmetros_Verm'!$D$25*'4.Parâmetros_Verm'!$F$25*'4.Parâmetros_Verm'!$G$25*'4.Parâmetros_Verm'!$H$25*'5.Mira'!$C$19*'6.Cibernético'!$C$24*'6.Cibernético'!$D$23*'9.Simulação'!$M$15)+('7.Config'!$C$12*'4.Parâmetros_Verm'!$D$34*'4.Parâmetros_Verm'!$F$34*'4.Parâmetros_Verm'!$G$34*'4.Parâmetros_Verm'!$H$34*'5.Mira'!$C$20*'6.Cibernético'!$C$24*'6.Cibernético'!$D$23*'9.Simulação'!$N$15)+('7.Config'!$C$12*'4.Parâmetros_Verm'!$D$43*'4.Parâmetros_Verm'!$F$43*'4.Parâmetros_Verm'!$G$43*'4.Parâmetros_Verm'!$H$43*'5.Mira'!$C$21*'6.Cibernético'!$C$24*'6.Cibernético'!$D$23*'9.Simulação'!$O$15) -> 0.96487729 | L5: =('7.Config'!$C$10*'4.Parâmetros_Verm'!$D$7*'4.Parâmetros_Verm'!$F$7*'4.Parâmetros_Verm'!$G$7*'4.Parâmetros_Verm'!$H$7*'5.Mira'!$C$17*'6.Cibernético'!$C$24*'6.Cibernético'!$D$23*'9.Simulação'!$K$16)+('7.Config'!$C$10*'4.Parâmetros_Verm'!$D$16*'4.Parâmetros_Verm'!$F$16*'4.Parâmetros_Verm'!$G$16*'4.Parâmetros_Verm'!$H$16*'5.Mira'!$C$18*'6.Cibernético'!$C$24*'6.Cibernético'!$D$23*'9.Simulação'!$L$16)+('7.Config'!$C$12*'4.Parâmetros_Verm'!$D$25*'4.Parâmetros_Verm'!$F$25*'4.Parâmetros_Verm'!$G$25*'4.Parâmetros_Verm'!$H$25*'5.Mira'!$C$19*'6.Cibernético'!$C$24*'6.Cibernético'!$D$23*'9.Simulação'!$M$16)+('7.Config'!$C$12*'4.Parâmetros_Verm'!$D$34*'4.Parâmetros_Verm'!$F$34*'4.Parâmetros_Verm'!$G$34*'4.Parâmetros_Verm'!$H$34*'5.Mira'!$C$20*'6.Cibernético'!$C$24*'6.Cibernético'!$D$23*'9.Simulação'!$N$16)+('7.Config'!$C$12*'4.Parâmetros_Verm'!$D$43*'4.Parâmetros_Verm'!$F$43*'4.Parâmetros_Verm'!$G$43*'4.Parâmetros_Verm'!$H$43*'5.Mira'!$C$21*'6.Cibernético'!$C$24*'6.Cibernético'!$D$23*'9.Simulação'!$O$16) -> 0.96106921
A6: Az_inc_sim | B6: Fragata Cl. Niterói mod | C6: =('7.Config'!$C$10*'4.Parâmetros_Verm'!$D$8*'4.Parâmetros_Verm'!$F$8*'4.Parâmetros_Verm'!$G$8*'4.Parâmetros_Verm'!$H$8*'5.Mira'!$D$17*'6.Cibernético'!$C$24*'6.Cibernético'!$D$23*'9.Simulação'!$K$7)+('7.Config'!$C$10*'4.Parâmetros_Verm'!$D$17*'4.Parâmetros_Verm'!$F$17*'4.Parâmetros_Verm'!$G$17*'4.Parâmetros_Verm'!$H$17*'5.Mira'!$D$18*'6.Cibernético'!$C$24*'6.Cibernético'!$D$23*'9.Simulação'!$L$7)+('7.Config'!$C$12*'4.Parâmetros_Verm'!$D$26*'4.Parâmetros_Verm'!$F$26*'4.Parâmetros_Verm'!$G$26*'4.Parâmetros_Verm'!$H$26*'5.Mira'!$D$19*'6.Cibernético'!$C$24*'6.Cibernético'!$D$23*'9.Simulação'!$M$7)+('7.Config'!$C$12*'4.Parâmetros_Verm'!$D$35*'4.Parâmetros_Verm'!$F$35*'4.Parâmetros_Verm'!$G$35*'4.Parâmetros_Verm'!$H$35*'5.Mira'!$D$20*'6.Cibernético'!$C$24*'6.Cibernético'!$D$23*'9.Simulação'!$N$7)+('7.Config'!$C$12*'4.Parâmetros_Verm'!$D$44*'4.Parâmetros_Verm'!$F$44*'4.Parâmetros_Verm'!$G$44*'4.Parâmetros_Verm'!$H$44*'5.Mira'!$D$21*'6.Cibernético'!$C$24*'6.Cibernético'!$D$23*'9.Simulação'!$O$7) -> 0.99445219 | D6: =('7.Config'!$C$10*'4.Parâmetros_Verm'!$D$8*'4.Parâmetros_Verm'!$F$8*'4.Parâmetros_Verm'!$G$8*'4.Parâmetros_Verm'!$H$8*'5.Mira'!$D$17*'6.Cibernético'!$C$24*'6.Cibernético'!$D$23*'9.Simulação'!$K$8)+('7.Config'!$C$10*'4.Parâmetros_Verm'!$D$17*'4.Parâmetros_Verm'!$F$17*'4.Parâmetros_Verm'!$G$17*'4.Parâmetros_Verm'!$H$17*'5.Mira'!$D$18*'6.Cibernético'!$C$24*'6.Cibernético'!$D$23*'9.Simulação'!$L$8)+('7.Config'!$C$12*'4.Parâmetros_Verm'!$D$26*'4.Parâmetros_Verm'!$F$26*'4.Parâmetros_Verm'!$G$26*'4.Parâmetros_Verm'!$H$26*'5.Mira'!$D$19*'6.Cibernético'!$C$24*'6.Cibernético'!$D$23*'9.Simulação'!$M$8)+('7.Config'!$C$12*'4.Parâmetros_Verm'!$D$35*'4.Parâmetros_Verm'!$F$35*'4.Parâmetros_Verm'!$G$35*'4.Parâmetros_Verm'!$H$35*'5.Mira'!$D$20*'6.Cibernético'!$C$24*'6.Cibernético'!$D$23*'9.Simulação'!$N$8)+('7.Config'!$C$12*'4.Parâmetros_Verm'!$D$44*'4.Parâmetros_Verm'!$F$44*'4.Parâmetros_Verm'!$G$44*'4.Parâmetros_Verm'!$H$44*'5.Mira'!$D$21*'6.Cibernético'!$C$24*'6.Cibernético'!$D$23*'9.Simulação'!$O$8) -> 0.99083924 | E6: =('7.Config'!$C$10*'4.Parâmetros_Verm'!$D$8*'4.Parâmetros_Verm'!$F$8*'4.Parâmetros_Verm'!$G$8*'4.Parâmetros_Verm'!$H$8*'5.Mira'!$D$17*'6.Cibernético'!$C$24*'6.Cibernético'!$D$23*'9.Simulação'!$K$9)+('7.Config'!$C$10*'4.Parâmetros_Verm'!$D$17*'4.Parâmetros_Verm'!$F$17*'4.Parâmetros_Verm'!$G$17*'4.Parâmetros_Verm'!$H$17*'5.Mira'!$D$18*'6.Cibernético'!$C$24*'6.Cibernético'!$D$23*'9.Simulação'!$L$9)+('7.Config'!$C$12*'4.Parâmetros_Verm'!$D$26*'4.Parâmetros_Verm'!$F$26*'4.Parâmetros_Verm'!$G$26*'4.Parâmetros_Verm'!$H$26*'5.Mira'!$D$19*'6.Cibernético'!$C$24*'6.Cibernético'!$D$23*'9.Simulação'!$M$9)+('7.Config'!$C$12*'4.Parâmetros_Verm'!$D$35*'4.Parâmetros_Verm'!$F$35*'4.Parâmetros_Verm'!$G$35*'4.Parâmetros_Verm'!$H$35*'5.Mira'!$D$20*'6.Cibernético'!$C$24*'6.Cibernético'!$D$23*'9.Simulação'!$N$9)+('7.Config'!$C$12*'4.Parâmetros_Verm'!$D$44*'4.Parâmetros_Verm'!$F$44*'4.Parâmetros_Verm'!$G$44*'4.Parâmetros_Verm'!$H$44*'5.Mira'!$D$21*'6.Cibernético'!$C$24*'6.Cibernético'!$D$23*'9.Simulação'!$O$9) -> 0.98720287 | F6: =('7.Config'!$C$10*'4.Parâmetros_Verm'!$D$8*'4.Parâmetros_Verm'!$F$8*'4.Parâmetros_Verm'!$G$8*'4.Parâmetros_Verm'!$H$8*'5.Mira'!$D$17*'6.Cibernético'!$C$24*'6.Cibernético'!$D$23*'9.Simulação'!$K$10)+('7.Config'!$C$10*'4.Parâmetros_Verm'!$D$17*'4.Parâmetros_Verm'!$F$17*'4.Parâmetros_Verm'!$G$17*'4.Parâmetros_Verm'!$H$17*'5.Mira'!$D$18*'6.Cibernético'!$C$24*'6.Cibernético'!$D$23*'9.Simulação'!$L$10)+('7.Config'!$C$12*'4.Parâmetros_Verm'!$D$26*'4.Parâmetros_Verm'!$F$26*'4.Parâmetros_Verm'!$G$26*'4.Parâmetros_Verm'!$H$26*'5.Mira'!$D$19*'6.Cibernético'!$C$24*'6.Cibernético'!$D$23*'9.Simulação'!$M$10)+('7.Config'!$C$12*'4.Parâmetros_Verm'!$D$35*'4.Parâmetros_Verm'!$F$35*'4.Parâmetros_Verm'!$G$35*'4.Parâmetros_Verm'!$H$35*'5.Mira'!$D$20*'6.Cibernético'!$C$24*'6.Cibernético'!$D$23*'9.Simulação'!$N$10)+('7.Config'!$C$12*'4.Parâmetros_Verm'!$D$44*'4.Parâmetros_Verm'!$F$44*'4.Parâmetros_Verm'!$G$44*'4.Parâmetros_Verm'!$H$44*'5.Mira'!$D$21*'6.Cibernético'!$C$24*'6.Cibernético'!$D$23*'9.Simulação'!$O$10) -> 0.98354281 | G6: =('7.Config'!$C$10*'4.Parâmetros_Verm'!$D$8*'4.Parâmetros_Verm'!$F$8*'4.Parâmetros_Verm'!$G$8*'4.Parâmetros_Verm'!$H$8*'5.Mira'!$D$17*'6.Cibernético'!$C$24*'6.Cibernético'!$D$23*'9.Simulação'!$K$11)+('7.Config'!$C$10*'4.Parâmetros_Verm'!$D$17*'4.Parâmetros_Verm'!$F$17*'4.Parâmetros_Verm'!$G$17*'4.Parâmetros_Verm'!$H$17*'5.Mira'!$D$18*'6.Cibernético'!$C$24*'6.Cibernético'!$D$23*'9.Simulação'!$L$11)+('7.Config'!$C$12*'4.Parâmetros_Verm'!$D$26*'4.Parâmetros_Verm'!$F$26*'4.Parâmetros_Verm'!$G$26*'4.Parâmetros_Verm'!$H$26*'5.Mira'!$D$19*'6.Cibernético'!$C$24*'6.Cibernético'!$D$23*'9.Simulação'!$M$11)+('7.Config'!$C$12*'4.Parâmetros_Verm'!$D$35*'4.Parâmetros_Verm'!$F$35*'4.Parâmetros_Verm'!$G$35*'4.Parâmetros_Verm'!$H$35*'5.Mira'!$D$20*'6.Cibernético'!$C$24*'6.Cibernético'!$D$23*'9.Simulação'!$N$11)+('7.Config'!$C$12*'4.Parâmetros_Verm'!$D$44*'4.Parâmetros_Verm'!$F$44*'4.Parâmetros_Verm'!$G$44*'4.Parâmetros_Verm'!$H$44*'5.Mira'!$D$21*'6.Cibernético'!$C$24*'6.Cibernético'!$D$23*'9.Simulação'!$O$11) -> 0.97985877 | H6: =('7.Config'!$C$10*'4.Parâmetros_Verm'!$D$8*'4.Parâmetros_Verm'!$F$8*'4.Parâmetros_Verm'!$G$8*'4.Parâmetros_Verm'!$H$8*'5.Mira'!$D$17*'6.Cibernético'!$C$24*'6.Cibernético'!$D$23*'9.Simulação'!$K$12)+('7.Config'!$C$10*'4.Parâmetros_Verm'!$D$17*'4.Parâmetros_Verm'!$F$17*'4.Parâmetros_Verm'!$G$17*'4.Parâmetros_Verm'!$H$17*'5.Mira'!$D$18*'6.Cibernético'!$C$24*'6.Cibernético'!$D$23*'9.Simulação'!$L$12)+('7.Config'!$C$12*'4.Parâmetros_Verm'!$D$26*'4.Parâmetros_Verm'!$F$26*'4.Parâmetros_Verm'!$G$26*'4.Parâmetros_Verm'!$H$26*'5.Mira'!$D$19*'6.Cibernético'!$C$24*'6.Cibernético'!$D$23*'9.Simulação'!$M$12)+('7.Config'!$C$12*'4.Parâmetros_Verm'!$D$35*'4.Parâmetros_Verm'!$F$35*'4.Parâmetros_Verm'!$G$35*'4.Parâmetros_Verm'!$H$35*'5.Mira'!$D$20*'6.Cibernético'!$C$24*'6.Cibernético'!$D$23*'9.Simulação'!$N$12)+('7.Config'!$C$12*'4.Parâmetros_Verm'!$D$44*'4.Parâmetros_Verm'!$F$44*'4.Parâmetros_Verm'!$G$44*'4.Parâmetros_Verm'!$H$44*'5.Mira'!$D$21*'6.Cibernético'!$C$24*'6.Cibernético'!$D$23*'9.Simulação'!$O$12) -> 0.97615047 | I6: =('7.Config'!$C$10*'4.Parâmetros_Verm'!$D$8*'4.Parâmetros_Verm'!$F$8*'4.Parâmetros_Verm'!$G$8*'4.Parâmetros_Verm'!$H$8*'5.Mira'!$D$17*'6.Cibernético'!$C$24*'6.Cibernético'!$D$23*'9.Simulação'!$K$13)+('7.Config'!$C$10*'4.Parâmetros_Verm'!$D$17*'4.Parâmetros_Verm'!$F$17*'4.Parâmetros_Verm'!$G$17*'4.Parâmetros_Verm'!$H$17*'5.Mira'!$D$18*'6.Cibernético'!$C$24*'6.Cibernético'!$D$23*'9.Simulação'!$L$13)+('7.Config'!$C$12*'4.Parâmetros_Verm'!$D$26*'4.Parâmetros_Verm'!$F$26*'4.Parâmetros_Verm'!$G$26*'4.Parâmetros_Verm'!$H$26*'5.Mira'!$D$19*'6.Cibernético'!$C$24*'6.Cibernético'!$D$23*'9.Simulação'!$M$13)+('7.Config'!$C$12*'4.Parâmetros_Verm'!$D$35*'4.Parâmetros_Verm'!$F$35*'4.Parâmetros_Verm'!$G$35*'4.Parâmetros_Verm'!$H$35*'5.Mira'!$D$20*'6.Cibernético'!$C$24*'6.Cibernético'!$D$23*'9.Simulação'!$N$13)+('7.Config'!$C$12*'4.Parâmetros_Verm'!$D$44*'4.Parâmetros_Verm'!$F$44*'4.Parâmetros_Verm'!$G$44*'4.Parâmetros_Verm'!$H$44*'5.Mira'!$D$21*'6.Cibernético'!$C$24*'6.Cibernético'!$D$23*'9.Simulação'!$O$13) -> 0.97241764 | J6: =('7.Config'!$C$10*'4.Parâmetros_Verm'!$D$8*'4.Parâmetros_Verm'!$F$8*'4.Parâmetros_Verm'!$G$8*'4.Parâmetros_Verm'!$H$8*'5.Mira'!$D$17*'6.Cibernético'!$C$24*'6.Cibernético'!$D$23*'9.Simulação'!$K$14)+('7.Config'!$C$10*'4.Parâmetros_Verm'!$D$17*'4.Parâmetros_Verm'!$F$17*'4.Parâmetros_Verm'!$G$17*'4.Parâmetros_Verm'!$H$17*'5.Mira'!$D$18*'6.Cibernético'!$C$24*'6.Cibernético'!$D$23*'9.Simulação'!$L$14)+('7.Config'!$C$12*'4.Parâmetros_Verm'!$D$26*'4.Parâmetros_Verm'!$F$26*'4.Parâmetros_Verm'!$G$26*'4.Parâmetros_Verm'!$H$26*'5.Mira'!$D$19*'6.Cibernético'!$C$24*'6.Cibernético'!$D$23*'9.Simulação'!$M$14)+('7.Config'!$C$12*'4.Parâmetros_Verm'!$D$35*'4.Parâmetros_Verm'!$F$35*'4.Parâmetros_Verm'!$G$35*'4.Parâmetros_Verm'!$H$35*'5.Mira'!$D$20*'6.Cibernético'!$C$24*'6.Cibernético'!$D$23*'9.Simulação'!$N$14)+('7.Config'!$C$12*'4.Parâmetros_Verm'!$D$44*'4.Parâmetros_Verm'!$F$44*'4.Parâmetros_Verm'!$G$44*'4.Parâmetros_Verm'!$H$44*'5.Mira'!$D$21*'6.Cibernético'!$C$24*'6.Cibernético'!$D$23*'9.Simulação'!$O$14) -> 0.96866001 | K6: =('7.Config'!$C$10*'4.Parâmetros_Verm'!$D$8*'4.Parâmetros_Verm'!$F$8*'4.Parâmetros_Verm'!$G$8*'4.Parâmetros_Verm'!$H$8*'5.Mira'!$D$17*'6.Cibernético'!$C$24*'6.Cibernético'!$D$23*'9.Simulação'!$K$15)+('7.Config'!$C$10*'4.Parâmetros_Verm'!$D$17*'4.Parâmetros_Verm'!$F$17*'4.Parâmetros_Verm'!$G$17*'4.Parâmetros_Verm'!$H$17*'5.Mira'!$D$18*'6.Cibernético'!$C$24*'6.Cibernético'!$D$23*'9.Simulação'!$L$15)+('7.Config'!$C$12*'4.Parâmetros_Verm'!$D$26*'4.Parâmetros_Verm'!$F$26*'4.Parâmetros_Verm'!$G$26*'4.Parâmetros_Verm'!$H$26*'5.Mira'!$D$19*'6.Cibernético'!$C$24*'6.Cibernético'!$D$23*'9.Simulação'!$M$15)+('7.Config'!$C$12*'4.Parâmetros_Verm'!$D$35*'4.Parâmetros_Verm'!$F$35*'4.Parâmetros_Verm'!$G$35*'4.Parâmetros_Verm'!$H$35*'5.Mira'!$D$20*'6.Cibernético'!$C$24*'6.Cibernético'!$D$23*'9.Simulação'!$N$15)+('7.Config'!$C$12*'4.Parâmetros_Verm'!$D$44*'4.Parâmetros_Verm'!$F$44*'4.Parâmetros_Verm'!$G$44*'4.Parâmetros_Verm'!$H$44*'5.Mira'!$D$21*'6.Cibernético'!$C$24*'6.Cibernético'!$D$23*'9.Simulação'!$O$15) -> 0.96487729 | L6: =('7.Config'!$C$10*'4.Parâmetros_Verm'!$D$8*'4.Parâmetros_Verm'!$F$8*'4.Parâmetros_Verm'!$G$8*'4.Parâmetros_Verm'!$H$8*'5.Mira'!$D$17*'6.Cibernético'!$C$24*'6.Cibernético'!$D$23*'9.Simulação'!$K$16)+('7.Config'!$C$10*'4.Parâmetros_Verm'!$D$17*'4.Parâmetros_Verm'!$F$17*'4.Parâmetros_Verm'!$G$17*'4.Parâmetros_Verm'!$H$17*'5.Mira'!$D$18*'6.Cibernético'!$C$24*'6.Cibernético'!$D$23*'9.Simulação'!$L$16)+('7.Config'!$C$12*'4.Parâmetros_Verm'!$D$26*'4.Parâmetros_Verm'!$F$26*'4.Parâmetros_Verm'!$G$26*'4.Parâmetros_Verm'!$H$26*'5.Mira'!$D$19*'6.Cibernético'!$C$24*'6.Cibernético'!$D$23*'9.Simulação'!$M$16)+('7.Config'!$C$12*'4.Parâmetros_Verm'!$D$35*'4.Parâmetros_Verm'!$F$35*'4.Parâmetros_Verm'!$G$35*'4.Parâmetros_Verm'!$H$35*'5.Mira'!$D$20*'6.Cibernético'!$C$24*'6.Cibernético'!$D$23*'9.Simulação'!$N$16)+('7.Config'!$C$12*'4.Parâmetros_Verm'!$D$44*'4.Parâmetros_Verm'!$F$44*'4.Parâmetros_Verm'!$G$44*'4.Parâmetros_Verm'!$H$44*'5.Mira'!$D$21*'6.Cibernético'!$C$24*'6.Cibernético'!$D$23*'9.Simulação'!$O$16) -> 0.96106921
A7: Az_inc_sim | B7: Submarino Cl. Riachuelo | C7: =('7.Config'!$D$10*'4.Parâmetros_Verm'!$D$9*'4.Parâmetros_Verm'!$F$9*'4.Parâmetros_Verm'!$G$9*'4.Parâmetros_Verm'!$H$9*'5.Mira'!$E$17*'6.Cibernético'!$C$24*'6.Cibernético'!$D$25*'9.Simulação'!$K$7)+('7.Config'!$D$10*'4.Parâmetros_Verm'!$D$18*'4.Parâmetros_Verm'!$F$18*'4.Parâmetros_Verm'!$G$18*'4.Parâmetros_Verm'!$H$18*'5.Mira'!$E$18*'6.Cibernético'!$C$24*'6.Cibernético'!$D$25*'9.Simulação'!$L$7)+('7.Config'!$D$12*'4.Parâmetros_Verm'!$D$27*'4.Parâmetros_Verm'!$F$27*'4.Parâmetros_Verm'!$G$27*'4.Parâmetros_Verm'!$H$27*'5.Mira'!$E$19*'6.Cibernético'!$C$24*'6.Cibernético'!$D$25*'9.Simulação'!$M$7)+('7.Config'!$D$12*'4.Parâmetros_Verm'!$D$36*'4.Parâmetros_Verm'!$F$36*'4.Parâmetros_Verm'!$G$36*'4.Parâmetros_Verm'!$H$36*'5.Mira'!$E$20*'6.Cibernético'!$C$24*'6.Cibernético'!$D$25*'9.Simulação'!$N$7)+('7.Config'!$D$12*'4.Parâmetros_Verm'!$D$45*'4.Parâmetros_Verm'!$F$45*'4.Parâmetros_Verm'!$G$45*'4.Parâmetros_Verm'!$H$45*'5.Mira'!$E$21*'6.Cibernético'!$C$24*'6.Cibernético'!$D$25*'9.Simulação'!$O$7) -> 0.131505 | D7: =('7.Config'!$D$10*'4.Parâmetros_Verm'!$D$9*'4.Parâmetros_Verm'!$F$9*'4.Parâmetros_Verm'!$G$9*'4.Parâmetros_Verm'!$H$9*'5.Mira'!$E$17*'6.Cibernético'!$C$24*'6.Cibernético'!$D$25*'9.Simulação'!$K$8)+('7.Config'!$D$10*'4.Parâmetros_Verm'!$D$18*'4.Parâmetros_Verm'!$F$18*'4.Parâmetros_Verm'!$G$18*'4.Parâmetros_Verm'!$H$18*'5.Mira'!$E$18*'6.Cibernético'!$C$24*'6.Cibernético'!$D$25*'9.Simulação'!$L$8)+('7.Config'!$D$12*'4.Parâmetros_Verm'!$D$27*'4.Parâmetros_Verm'!$F$27*'4.Parâmetros_Verm'!$G$27*'4.Parâmetros_Verm'!$H$27*'5.Mira'!$E$19*'6.Cibernético'!$C$24*'6.Cibernético'!$D$25*'9.Simulação'!$M$8)+('7.Config'!$D$12*'4.Parâmetros_Verm'!$D$36*'4.Parâmetros_Verm'!$F$36*'4.Parâmetros_Verm'!$G$36*'4.Parâmetros_Verm'!$H$36*'5.Mira'!$E$20*'6.Cibernético'!$C$24*'6.Cibernético'!$D$25*'9.Simulação'!$N$8)+('7.Config'!$D$12*'4.Parâmetros_Verm'!$D$45*'4.Parâmetros_Verm'!$F$45*'4.Parâmetros_Verm'!$G$45*'4.Parâmetros_Verm'!$H$45*'5.Mira'!$E$21*'6.Cibernético'!$C$24*'6.Cibernético'!$D$25*'9.Simulação'!$O$8) -> 0.13080951 | E7: =('7.Config'!$D$10*'4.Parâmetros_Verm'!$D$9*'4.Parâmetros_Verm'!$F$9*'4.Parâmetros_Verm'!$G$9*'4.Parâmetros_Verm'!$H$9*'5.Mira'!$E$17*'6.Cibernético'!$C$24*'6.Cibernético'!$D$25*'9.Simulação'!$K$9)+('7.Config'!$D$10*'4.Parâmetros_Verm'!$D$18*'4.Parâmetros_Verm'!$F$18*'4.Parâmetros_Verm'!$G$18*'4.Parâmetros_Verm'!$H$18*'5.Mira'!$E$18*'6.Cibernético'!$C$24*'6.Cibernético'!$D$25*'9.Simulação'!$L$9)+('7.Config'!$D$12*'4.Parâmetros_Verm'!$D$27*'4.Parâmetros_Verm'!$F$27*'4.Parâmetros_Verm'!$G$27*'4.Parâmetros_Verm'!$H$27*'5.Mira'!$E$19*'6.Cibernético'!$C$24*'6.Cibernético'!$D$25*'9.Simulação'!$M$9)+('7.Config'!$D$12*'4.Parâmetros_Verm'!$D$36*'4.Parâmetros_Verm'!$F$36*'4.Parâmetros_Verm'!$G$36*'4.Parâmetros_Verm'!$H$36*'5.Mira'!$E$20*'6.Cibernético'!$C$24*'6.Cibernético'!$D$25*'9.Simulação'!$N$9)+('7.Config'!$D$12*'4.Parâmetros_Verm'!$D$45*'4.Parâmetros_Verm'!$F$45*'4.Parâmetros_Verm'!$G$45*'4.Parâmetros_Verm'!$H$45*'5.Mira'!$E$21*'6.Cibernético'!$C$24*'6.Cibernético'!$D$25*'9.Simulação'!$O$9) -> 0.13010951 | F7: =('7.Config'!$D$10*'4.Parâmetros_Verm'!$D$9*'4.Parâmetros_Verm'!$F$9*'4.Parâmetros_Verm'!$G$9*'4.Parâmetros_Verm'!$H$9*'5.Mira'!$E$17*'6.Cibernético'!$C$24*'6.Cibernético'!$D$25*'9.Simulação'!$K$10)+('7.Config'!$D$10*'4.Parâmetros_Verm'!$D$18*'4.Parâmetros_Verm'!$F$18*'4.Parâmetros_Verm'!$G$18*'4.Parâmetros_Verm'!$H$18*'5.Mira'!$E$18*'6.Cibernético'!$C$24*'6.Cibernético'!$D$25*'9.Simulação'!$L$10)+('7.Config'!$D$12*'4.Parâmetros_Verm'!$D$27*'4.Parâmetros_Verm'!$F$27*'4.Parâmetros_Verm'!$G$27*'4.Parâmetros_Verm'!$H$27*'5.Mira'!$E$19*'6.Cibernético'!$C$24*'6.Cibernético'!$D$25*'9.Simulação'!$M$10)+('7.Config'!$D$12*'4.Parâmetros_Verm'!$D$36*'4.Parâmetros_Verm'!$F$36*'4.Parâmetros_Verm'!$G$36*'4.Parâmetros_Verm'!$H$36*'5.Mira'!$E$20*'6.Cibernético'!$C$24*'6.Cibernético'!$D$25*'9.Simulação'!$N$10)+('7.Config'!$D$12*'4.Parâmetros_Verm'!$D$45*'4.Parâmetros_Verm'!$F$45*'4.Parâmetros_Verm'!$G$45*'4.Parâmetros_Verm'!$H$45*'5.Mira'!$E$21*'6.Cibernético'!$C$24*'6.Cibernético'!$D$25*'9.Simulação'!$O$10) -> 0.12940494 | G7: =('7.Config'!$D$10*'4.Parâmetros_Verm'!$D$9*'4.Parâmetros_Verm'!$F$9*'4.Parâmetros_Verm'!$G$9*'4.Parâmetros_Verm'!$H$9*'5.Mira'!$E$17*'6.Cibernético'!$C$24*'6.Cibernético'!$D$25*'9.Simulação'!$K$11)+('7.Config'!$D$10*'4.Parâmetros_Verm'!$D$18*'4.Parâmetros_Verm'!$F$18*'4.Parâmetros_Verm'!$G$18*'4.Parâmetros_Verm'!$H$18*'5.Mira'!$E$18*'6.Cibernético'!$C$24*'6.Cibernético'!$D$25*'9.Simulação'!$L$11)+('7.Config'!$D$12*'4.Parâmetros_Verm'!$D$27*'4.Parâmetros_Verm'!$F$27*'4.Parâmetros_Verm'!$G$27*'4.Parâmetros_Verm'!$H$27*'5.Mira'!$E$19*'6.Cibernético'!$C$24*'6.Cibernético'!$D$25*'9.Simulação'!$M$11)+('7.Config'!$D$12*'4.Parâmetros_Verm'!$D$36*'4.Parâmetros_Verm'!$F$36*'4.Parâmetros_Verm'!$G$36*'4.Parâmetros_Verm'!$H$36*'5.Mira'!$E$20*'6.Cibernético'!$C$24*'6.Cibernético'!$D$25*'9.Simulação'!$N$11)+('7.Config'!$D$12*'4.Parâmetros_Verm'!$D$45*'4.Parâmetros_Verm'!$F$45*'4.Parâmetros_Verm'!$G$45*'4.Parâmetros_Verm'!$H$45*'5.Mira'!$E$21*'6.Cibernético'!$C$24*'6.Cibernético'!$D$25*'9.Simulação'!$O$11) -> 0.12869577 | H7: =('7.Config'!$D$10*'4.Parâmetros_Verm'!$D$9*'4.Parâmetros_Verm'!$F$9*'4.Parâmetros_Verm'!$G$9*'4.Parâmetros_Verm'!$H$9*'5.Mira'!$E$17*'6.Cibernético'!$C$24*'6.Cibernético'!$D$25*'9.Simulação'!$K$12)+('7.Config'!$D$10*'4.Parâmetros_Verm'!$D$18*'4.Parâmetros_Verm'!$F$18*'4.Parâmetros_Verm'!$G$18*'4.Parâmetros_Verm'!$H$18*'5.Mira'!$E$18*'6.Cibernético'!$C$24*'6.Cibernético'!$D$25*'9.Simulação'!$L$12)+('7.Config'!$D$12*'4.Parâmetros_Verm'!$D$27*'4.Parâmetros_Verm'!$F$27*'4.Parâmetros_Verm'!$G$27*'4.Parâmetros_Verm'!$H$27*'5.Mira'!$E$19*'6.Cibernético'!$C$24*'6.Cibernético'!$D$25*'9.Simulação'!$M$12)+('7.Config'!$D$12*'4.Parâmetros_Verm'!$D$36*'4.Parâmetros_Verm'!$F$36*'4.Parâmetros_Verm'!$G$36*'4.Parâmetros_Verm'!$H$36*'5.Mira'!$E$20*'6.Cibernético'!$C$24*'6.Cibernético'!$D$25*'9.Simulação'!$N$12)+('7.Config'!$D$12*'4.Parâmetros_Verm'!$D$45*'4.Parâmetros_Verm'!$F$45*'4.Parâmetros_Verm'!$G$45*'4.Parâmetros_Verm'!$H$45*'5.Mira'!$E$21*'6.Cibernético'!$C$24*'6.Cibernético'!$D$25*'9.Simulação'!$O$12) -> 0.12798192 | I7: =('7.Config'!$D$10*'4.Parâmetros_Verm'!$D$9*'4.Parâmetros_Verm'!$F$9*'4.Parâmetros_Verm'!$G$9*'4.Parâmetros_Verm'!$H$9*'5.Mira'!$E$17*'6.Cibernético'!$C$24*'6.Cibernético'!$D$25*'9.Simulação'!$K$13)+('7.Config'!$D$10*'4.Parâmetros_Verm'!$D$18*'4.Parâmetros_Verm'!$F$18*'4.Parâmetros_Verm'!$G$18*'4.Parâmetros_Verm'!$H$18*'5.Mira'!$E$18*'6.Cibernético'!$C$24*'6.Cibernético'!$D$25*'9.Simulação'!$L$13)+('7.Config'!$D$12*'4.Parâmetros_Verm'!$D$27*'4.Parâmetros_Verm'!$F$27*'4.Parâmetros_Verm'!$G$27*'4.Parâmetros_Verm'!$H$27*'5.Mira'!$E$19*'6.Cibernético'!$C$24*'6.Cibernético'!$D$25*'9.Simulação'!$M$13)+('7.Config'!$D$12*'4.Parâmetros_Verm'!$D$36*'4.Parâmetros_Verm'!$F$36*'4.Parâmetros_Verm'!$G$36*'4.Parâmetros_Verm'!$H$36*'5.Mira'!$E$20*'6.Cibernético'!$C$24*'6.Cibernético'!$D$25*'9.Simulação'!$N$13)+('7.Config'!$D$12*'4.Parâmetros_Verm'!$D$45*'4.Parâmetros_Verm'!$F$45*'4.Parâmetros_Verm'!$G$45*'4.Parâmetros_Verm'!$H$45*'5.Mira'!$E$21*'6.Cibernético'!$C$24*'6.Cibernético'!$D$25*'9.Simulação'!$O$13) -> 0.12726335 | J7: =('7.Config'!$D$10*'4.Parâmetros_Verm'!$D$9*'4.Parâmetros_Verm'!$F$9*'4.Parâmetros_Verm'!$G$9*'4.Parâmetros_Verm'!$H$9*'5.Mira'!$E$17*'6.Cibernético'!$C$24*'6.Cibernético'!$D$25*'9.Simulação'!$K$14)+('7.Config'!$D$10*'4.Parâmetros_Verm'!$D$18*'4.Parâmetros_Verm'!$F$18*'4.Parâmetros_Verm'!$G$18*'4.Parâmetros_Verm'!$H$18*'5.Mira'!$E$18*'6.Cibernético'!$C$24*'6.Cibernético'!$D$25*'9.Simulação'!$L$14)+('7.Config'!$D$12*'4.Parâmetros_Verm'!$D$27*'4.Parâmetros_Verm'!$F$27*'4.Parâmetros_Verm'!$G$27*'4.Parâmetros_Verm'!$H$27*'5.Mira'!$E$19*'6.Cibernético'!$C$24*'6.Cibernético'!$D$25*'9.Simulação'!$M$14)+('7.Config'!$D$12*'4.Parâmetros_Verm'!$D$36*'4.Parâmetros_Verm'!$F$36*'4.Parâmetros_Verm'!$G$36*'4.Parâmetros_Verm'!$H$36*'5.Mira'!$E$20*'6.Cibernético'!$C$24*'6.Cibernético'!$D$25*'9.Simulação'!$N$14)+('7.Config'!$D$12*'4.Parâmetros_Verm'!$D$45*'4.Parâmetros_Verm'!$F$45*'4.Parâmetros_Verm'!$G$45*'4.Parâmetros_Verm'!$H$45*'5.Mira'!$E$21*'6.Cibernético'!$C$24*'6.Cibernético'!$D$25*'9.Simulação'!$O$14) -> 0.12654001 | K7: =('7.Config'!$D$10*'4.Parâmetros_Verm'!$D$9*'4.Parâmetros_Verm'!$F$9*'4.Parâmetros_Verm'!$G$9*'4.Parâmetros_Verm'!$H$9*'5.Mira'!$E$17*'6.Cibernético'!$C$24*'6.Cibernético'!$D$25*'9.Simulação'!$K$15)+('7.Config'!$D$10*'4.Parâmetros_Verm'!$D$18*'4.Parâmetros_Verm'!$F$18*'4.Parâmetros_Verm'!$G$18*'4.Parâmetros_Verm'!$H$18*'5.Mira'!$E$18*'6.Cibernético'!$C$24*'6.Cibernético'!$D$25*'9.Simulação'!$L$15)+('7.Config'!$D$12*'4.Parâmetros_Verm'!$D$27*'4.Parâmetros_Verm'!$F$27*'4.Parâmetros_Verm'!$G$27*'4.Parâmetros_Verm'!$H$27*'5.Mira'!$E$19*'6.Cibernético'!$C$24*'6.Cibernético'!$D$25*'9.Simulação'!$M$15)+('7.Config'!$D$12*'4.Parâmetros_Verm'!$D$36*'4.Parâmetros_Verm'!$F$36*'4.Parâmetros_Verm'!$G$36*'4.Parâmetros_Verm'!$H$36*'5.Mira'!$E$20*'6.Cibernético'!$C$24*'6.Cibernético'!$D$25*'9.Simulação'!$N$15)+('7.Config'!$D$12*'4.Parâmetros_Verm'!$D$45*'4.Parâmetros_Verm'!$F$45*'4.Parâmetros_Verm'!$G$45*'4.Parâmetros_Verm'!$H$45*'5.Mira'!$E$21*'6.Cibernético'!$C$24*'6.Cibernético'!$D$25*'9.Simulação'!$O$15) -> 0.12581183 | L7: =('7.Config'!$D$10*'4.Parâmetros_Verm'!$D$9*'4.Parâmetros_Verm'!$F$9*'4.Parâmetros_Verm'!$G$9*'4.Parâmetros_Verm'!$H$9*'5.Mira'!$E$17*'6.Cibernético'!$C$24*'6.Cibernético'!$D$25*'9.Simulação'!$K$16)+('7.Config'!$D$10*'4.Parâmetros_Verm'!$D$18*'4.Parâmetros_Verm'!$F$18*'4.Parâmetros_Verm'!$G$18*'4.Parâmetros_Verm'!$H$18*'5.Mira'!$E$18*'6.Cibernético'!$C$24*'6.Cibernético'!$D$25*'9.Simulação'!$L$16)+('7.Config'!$D$12*'4.Parâmetros_Verm'!$D$27*'4.Parâmetros_Verm'!$F$27*'4.Parâmetros_Verm'!$G$27*'4.Parâmetros_Verm'!$H$27*'5.Mira'!$E$19*'6.Cibernético'!$C$24*'6.Cibernético'!$D$25*'9.Simulação'!$M$16)+('7.Config'!$D$12*'4.Parâmetros_Verm'!$D$36*'4.Parâmetros_Verm'!$F$36*'4.Parâmetros_Verm'!$G$36*'4.Parâmetros_Verm'!$H$36*'5.Mira'!$E$20*'6.Cibernético'!$C$24*'6.Cibernético'!$D$25*'9.Simulação'!$N$16)+('7.Config'!$D$12*'4.Parâmetros_Verm'!$D$45*'4.Parâmetros_Verm'!$F$45*'4.Parâmetros_Verm'!$G$45*'4.Parâmetros_Verm'!$H$45*'5.Mira'!$E$21*'6.Cibernético'!$C$24*'6.Cibernético'!$D$25*'9.Simulação'!$O$16) -> 0.12507878
A8: Az_inc_sim | B8: Aeronave P-3AM | C8: =('7.Config'!$E$10*'4.Parâmetros_Verm'!$D$10*'4.Parâmetros_Verm'!$F$10*'4.Parâmetros_Verm'!$G$10*'4.Parâmetros_Verm'!$H$10*'5.Mira'!$F$17*'6.Cibernético'!$C$24*'6.Cibernético'!$D$23*'9.Simulação'!$K$7)+('7.Config'!$E$10*'4.Parâmetros_Verm'!$D$19*'4.Parâmetros_Verm'!$F$19*'4.Parâmetros_Verm'!$G$19*'4.Parâmetros_Verm'!$H$19*'5.Mira'!$F$18*'6.Cibernético'!$C$24*'6.Cibernético'!$D$23*'9.Simulação'!$L$7)+('7.Config'!$E$12*'4.Parâmetros_Verm'!$D$28*'4.Parâmetros_Verm'!$F$28*'4.Parâmetros_Verm'!$G$28*'4.Parâmetros_Verm'!$H$28*'5.Mira'!$F$19*'6.Cibernético'!$C$24*'6.Cibernético'!$D$23*'9.Simulação'!$M$7)+('7.Config'!$E$12*'4.Parâmetros_Verm'!$D$37*'4.Parâmetros_Verm'!$F$37*'4.Parâmetros_Verm'!$G$37*'4.Parâmetros_Verm'!$H$37*'5.Mira'!$F$20*'6.Cibernético'!$C$24*'6.Cibernético'!$D$23*'9.Simulação'!$N$7)+('7.Config'!$E$12*'4.Parâmetros_Verm'!$D$46*'4.Parâmetros_Verm'!$F$46*'4.Parâmetros_Verm'!$G$46*'4.Parâmetros_Verm'!$H$46*'5.Mira'!$F$21*'6.Cibernético'!$C$24*'6.Cibernético'!$D$23*'9.Simulação'!$O$7) -> 0.39684375 | D8: =('7.Config'!$E$10*'4.Parâmetros_Verm'!$D$10*'4.Parâmetros_Verm'!$F$10*'4.Parâmetros_Verm'!$G$10*'4.Parâmetros_Verm'!$H$10*'5.Mira'!$F$17*'6.Cibernético'!$C$24*'6.Cibernético'!$D$23*'9.Simulação'!$K$8)+('7.Config'!$E$10*'4.Parâmetros_Verm'!$D$19*'4.Parâmetros_Verm'!$F$19*'4.Parâmetros_Verm'!$G$19*'4.Parâmetros_Verm'!$H$19*'5.Mira'!$F$18*'6.Cibernético'!$C$24*'6.Cibernético'!$D$23*'9.Simulação'!$L$8)+('7.Config'!$E$12*'4.Parâmetros_Verm'!$D$28*'4.Parâmetros_Verm'!$F$28*'4.Parâmetros_Verm'!$G$28*'4.Parâmetros_Verm'!$H$28*'5.Mira'!$F$19*'6.Cibernético'!$C$24*'6.Cibernético'!$D$23*'9.Simulação'!$M$8)+('7.Config'!$E$12*'4.Parâmetros_Verm'!$D$37*'4.Parâmetros_Verm'!$F$37*'4.Parâmetros_Verm'!$G$37*'4.Parâmetros_Verm'!$H$37*'5.Mira'!$F$20*'6.Cibernético'!$C$24*'6.Cibernético'!$D$23*'9.Simulação'!$N$8)+('7.Config'!$E$12*'4.Parâmetros_Verm'!$D$46*'4.Parâmetros_Verm'!$F$46*'4.Parâmetros_Verm'!$G$46*'4.Parâmetros_Verm'!$H$46*'5.Mira'!$F$21*'6.Cibernético'!$C$24*'6.Cibernético'!$D$23*'9.Simulação'!$O$8) -> 0.39526309 | E8: =('7.Config'!$E$10*'4.Parâmetros_Verm'!$D$10*'4.Parâmetros_Verm'!$F$10*'4.Parâmetros_Verm'!$G$10*'4.Parâmetros_Verm'!$H$10*'5.Mira'!$F$17*'6.Cibernético'!$C$24*'6.Cibernético'!$D$23*'9.Simulação'!$K$9)+('7.Config'!$E$10*'4.Parâmetros_Verm'!$D$19*'4.Parâmetros_Verm'!$F$19*'4.Parâmetros_Verm'!$G$19*'4.Parâmetros_Verm'!$H$19*'5.Mira'!$F$18*'6.Cibernético'!$C$24*'6.Cibernético'!$D$23*'9.Simulação'!$L$9)+('7.Config'!$E$12*'4.Parâmetros_Verm'!$D$28*'4.Parâmetros_Verm'!$F$28*'4.Parâmetros_Verm'!$G$28*'4.Parâmetros_Verm'!$H$28*'5.Mira'!$F$19*'6.Cibernético'!$C$24*'6.Cibernético'!$D$23*'9.Simulação'!$M$9)+('7.Config'!$E$12*'4.Parâmetros_Verm'!$D$37*'4.Parâmetros_Verm'!$F$37*'4.Parâmetros_Verm'!$G$37*'4.Parâmetros_Verm'!$H$37*'5.Mira'!$F$20*'6.Cibernético'!$C$24*'6.Cibernético'!$D$23*'9.Simulação'!$N$9)+('7.Config'!$E$12*'4.Parâmetros_Verm'!$D$46*'4.Parâmetros_Verm'!$F$46*'4.Parâmetros_Verm'!$G$46*'4.Parâmetros_Verm'!$H$46*'5.Mira'!$F$21*'6.Cibernético'!$C$24*'6.Cibernético'!$D$23*'9.Simulação'!$O$9) -> 0.39367217 | F8: =('7.Config'!$E$10*'4.Parâmetros_Verm'!$D$10*'4.Parâmetros_Verm'!$F$10*'4.Parâmetros_Verm'!$G$10*'4.Parâmetros_Verm'!$H$10*'5.Mira'!$F$17*'6.Cibernético'!$C$24*'6.Cibernético'!$D$23*'9.Simulação'!$K$10)+('7.Config'!$E$10*'4.Parâmetros_Verm'!$D$19*'4.Parâmetros_Verm'!$F$19*'4.Parâmetros_Verm'!$G$19*'4.Parâmetros_Verm'!$H$19*'5.Mira'!$F$18*'6.Cibernético'!$C$24*'6.Cibernético'!$D$23*'9.Simulação'!$L$10)+('7.Config'!$E$12*'4.Parâmetros_Verm'!$D$28*'4.Parâmetros_Verm'!$F$28*'4.Parâmetros_Verm'!$G$28*'4.Parâmetros_Verm'!$H$28*'5.Mira'!$F$19*'6.Cibernético'!$C$24*'6.Cibernético'!$D$23*'9.Simulação'!$M$10)+('7.Config'!$E$12*'4.Parâmetros_Verm'!$D$37*'4.Parâmetros_Verm'!$F$37*'4.Parâmetros_Verm'!$G$37*'4.Parâmetros_Verm'!$H$37*'5.Mira'!$F$20*'6.Cibernético'!$C$24*'6.Cibernético'!$D$23*'9.Simulação'!$N$10)+('7.Config'!$E$12*'4.Parâmetros_Verm'!$D$46*'4.Parâmetros_Verm'!$F$46*'4.Parâmetros_Verm'!$G$46*'4.Parâmetros_Verm'!$H$46*'5.Mira'!$F$21*'6.Cibernético'!$C$24*'6.Cibernético'!$D$23*'9.Simulação'!$O$10) -> 0.3920709 | G8: =('7.Config'!$E$10*'4.Parâmetros_Verm'!$D$10*'4.Parâmetros_Verm'!$F$10*'4.Parâmetros_Verm'!$G$10*'4.Parâmetros_Verm'!$H$10*'5.Mira'!$F$17*'6.Cibernético'!$C$24*'6.Cibernético'!$D$23*'9.Simulação'!$K$11)+('7.Config'!$E$10*'4.Parâmetros_Verm'!$D$19*'4.Parâmetros_Verm'!$F$19*'4.Parâmetros_Verm'!$G$19*'4.Parâmetros_Verm'!$H$19*'5.Mira'!$F$18*'6.Cibernético'!$C$24*'6.Cibernético'!$D$23*'9.Simulação'!$L$11)+('7.Config'!$E$12*'4.Parâmetros_Verm'!$D$28*'4.Parâmetros_Verm'!$F$28*'4.Parâmetros_Verm'!$G$28*'4.Parâmetros_Verm'!$H$28*'5.Mira'!$F$19*'6.Cibernético'!$C$24*'6.Cibernético'!$D$23*'9.Simulação'!$M$11)+('7.Config'!$E$12*'4.Parâmetros_Verm'!$D$37*'4.Parâmetros_Verm'!$F$37*'4.Parâmetros_Verm'!$G$37*'4.Parâmetros_Verm'!$H$37*'5.Mira'!$F$20*'6.Cibernético'!$C$24*'6.Cibernético'!$D$23*'9.Simulação'!$N$11)+('7.Config'!$E$12*'4.Parâmetros_Verm'!$D$46*'4.Parâmetros_Verm'!$F$46*'4.Parâmetros_Verm'!$G$46*'4.Parâmetros_Verm'!$H$46*'5.Mira'!$F$21*'6.Cibernético'!$C$24*'6.Cibernético'!$D$23*'9.Simulação'!$O$11) -> 0.39045913 | H8: =('7.Config'!$E$10*'4.Parâmetros_Verm'!$D$10*'4.Parâmetros_Verm'!$F$10*'4.Parâmetros_Verm'!$G$10*'4.Parâmetros_Verm'!$H$10*'5.Mira'!$F$17*'6.Cibernético'!$C$24*'6.Cibernético'!$D$23*'9.Simulação'!$K$12)+('7.Config'!$E$10*'4.Parâmetros_Verm'!$D$19*'4.Parâmetros_Verm'!$F$19*'4.Parâmetros_Verm'!$G$19*'4.Parâmetros_Verm'!$H$19*'5.Mira'!$F$18*'6.Cibernético'!$C$24*'6.Cibernético'!$D$23*'9.Simulação'!$L$12)+('7.Config'!$E$12*'4.Parâmetros_Verm'!$D$28*'4.Parâmetros_Verm'!$F$28*'4.Parâmetros_Verm'!$G$28*'4.Parâmetros_Verm'!$H$28*'5.Mira'!$F$19*'6.Cibernético'!$C$24*'6.Cibernético'!$D$23*'9.Simulação'!$M$12)+('7.Config'!$E$12*'4.Parâmetros_Verm'!$D$37*'4.Parâmetros_Verm'!$F$37*'4.Parâmetros_Verm'!$G$37*'4.Parâmetros_Verm'!$H$37*'5.Mira'!$F$20*'6.Cibernético'!$C$24*'6.Cibernético'!$D$23*'9.Simulação'!$N$12)+('7.Config'!$E$12*'4.Parâmetros_Verm'!$D$46*'4.Parâmetros_Verm'!$F$46*'4.Parâmetros_Verm'!$G$46*'4.Parâmetros_Verm'!$H$46*'5.Mira'!$F$21*'6.Cibernético'!$C$24*'6.Cibernético'!$D$23*'9.Simulação'!$O$12) -> 0.38883675 | I8: =('7.Config'!$E$10*'4.Parâmetros_Verm'!$D$10*'4.Parâmetros_Verm'!$F$10*'4.Parâmetros_Verm'!$G$10*'4.Parâmetros_Verm'!$H$10*'5.Mira'!$F$17*'6.Cibernético'!$C$24*'6.Cibernético'!$D$23*'9.Simulação'!$K$13)+('7.Config'!$E$10*'4.Parâmetros_Verm'!$D$19*'4.Parâmetros_Verm'!$F$19*'4.Parâmetros_Verm'!$G$19*'4.Parâmetros_Verm'!$H$19*'5.Mira'!$F$18*'6.Cibernético'!$C$24*'6.Cibernético'!$D$23*'9.Simulação'!$L$13)+('7.Config'!$E$12*'4.Parâmetros_Verm'!$D$28*'4.Parâmetros_Verm'!$F$28*'4.Parâmetros_Verm'!$G$28*'4.Parâmetros_Verm'!$H$28*'5.Mira'!$F$19*'6.Cibernético'!$C$24*'6.Cibernético'!$D$23*'9.Simulação'!$M$13)+('7.Config'!$E$12*'4.Parâmetros_Verm'!$D$37*'4.Parâmetros_Verm'!$F$37*'4.Parâmetros_Verm'!$G$37*'4.Parâmetros_Verm'!$H$37*'5.Mira'!$F$20*'6.Cibernético'!$C$24*'6.Cibernético'!$D$23*'9.Simulação'!$N$13)+('7.Config'!$E$12*'4.Parâmetros_Verm'!$D$46*'4.Parâmetros_Verm'!$F$46*'4.Parâmetros_Verm'!$G$46*'4.Parâmetros_Verm'!$H$46*'5.Mira'!$F$21*'6.Cibernético'!$C$24*'6.Cibernético'!$D$23*'9.Simulação'!$O$13) -> 0.38720364 | J8: =('7.Config'!$E$10*'4.Parâmetros_Verm'!$D$10*'4.Parâmetros_Verm'!$F$10*'4.Parâmetros_Verm'!$G$10*'4.Parâmetros_Verm'!$H$10*'5.Mira'!$F$17*'6.Cibernético'!$C$24*'6.Cibernético'!$D$23*'9.Simulação'!$K$14)+('7.Config'!$E$10*'4.Parâmetros_Verm'!$D$19*'4.Parâmetros_Verm'!$F$19*'4.Parâmetros_Verm'!$G$19*'4.Parâmetros_Verm'!$H$19*'5.Mira'!$F$18*'6.Cibernético'!$C$24*'6.Cibernético'!$D$23*'9.Simulação'!$L$14)+('7.Config'!$E$12*'4.Parâmetros_Verm'!$D$28*'4.Parâmetros_Verm'!$F$28*'4.Parâmetros_Verm'!$G$28*'4.Parâmetros_Verm'!$H$28*'5.Mira'!$F$19*'6.Cibernético'!$C$24*'6.Cibernético'!$D$23*'9.Simulação'!$M$14)+('7.Config'!$E$12*'4.Parâmetros_Verm'!$D$37*'4.Parâmetros_Verm'!$F$37*'4.Parâmetros_Verm'!$G$37*'4.Parâmetros_Verm'!$H$37*'5.Mira'!$F$20*'6.Cibernético'!$C$24*'6.Cibernético'!$D$23*'9.Simulação'!$N$14)+('7.Config'!$E$12*'4.Parâmetros_Verm'!$D$46*'4.Parâmetros_Verm'!$F$46*'4.Parâmetros_Verm'!$G$46*'4.Parâmetros_Verm'!$H$46*'5.Mira'!$F$21*'6.Cibernético'!$C$24*'6.Cibernético'!$D$23*'9.Simulação'!$O$14) -> 0.38555967 | K8: =('7.Config'!$E$10*'4.Parâmetros_Verm'!$D$10*'4.Parâmetros_Verm'!$F$10*'4.Parâmetros_Verm'!$G$10*'4.Parâmetros_Verm'!$H$10*'5.Mira'!$F$17*'6.Cibernético'!$C$24*'6.Cibernético'!$D$23*'9.Simulação'!$K$15)+('7.Config'!$E$10*'4.Parâmetros_Verm'!$D$19*'4.Parâmetros_Verm'!$F$19*'4.Parâmetros_Verm'!$G$19*'4.Parâmetros_Verm'!$H$19*'5.Mira'!$F$18*'6.Cibernético'!$C$24*'6.Cibernético'!$D$23*'9.Simulação'!$L$15)+('7.Config'!$E$12*'4.Parâmetros_Verm'!$D$28*'4.Parâmetros_Verm'!$F$28*'4.Parâmetros_Verm'!$G$28*'4.Parâmetros_Verm'!$H$28*'5.Mira'!$F$19*'6.Cibernético'!$C$24*'6.Cibernético'!$D$23*'9.Simulação'!$M$15)+('7.Config'!$E$12*'4.Parâmetros_Verm'!$D$37*'4.Parâmetros_Verm'!$F$37*'4.Parâmetros_Verm'!$G$37*'4.Parâmetros_Verm'!$H$37*'5.Mira'!$F$20*'6.Cibernético'!$C$24*'6.Cibernético'!$D$23*'9.Simulação'!$N$15)+('7.Config'!$E$12*'4.Parâmetros_Verm'!$D$46*'4.Parâmetros_Verm'!$F$46*'4.Parâmetros_Verm'!$G$46*'4.Parâmetros_Verm'!$H$46*'5.Mira'!$F$21*'6.Cibernético'!$C$24*'6.Cibernético'!$D$23*'9.Simulação'!$O$15) -> 0.38390473 | L8: =('7.Config'!$E$10*'4.Parâmetros_Verm'!$D$10*'4.Parâmetros_Verm'!$F$10*'4.Parâmetros_Verm'!$G$10*'4.Parâmetros_Verm'!$H$10*'5.Mira'!$F$17*'6.Cibernético'!$C$24*'6.Cibernético'!$D$23*'9.Simulação'!$K$16)+('7.Config'!$E$10*'4.Parâmetros_Verm'!$D$19*'4.Parâmetros_Verm'!$F$19*'4.Parâmetros_Verm'!$G$19*'4.Parâmetros_Verm'!$H$19*'5.Mira'!$F$18*'6.Cibernético'!$C$24*'6.Cibernético'!$D$23*'9.Simulação'!$L$16)+('7.Config'!$E$12*'4.Parâmetros_Verm'!$D$28*'4.Parâmetros_Verm'!$F$28*'4.Parâmetros_Verm'!$G$28*'4.Parâmetros_Verm'!$H$28*'5.Mira'!$F$19*'6.Cibernético'!$C$24*'6.Cibernético'!$D$23*'9.Simulação'!$M$16)+('7.Config'!$E$12*'4.Parâmetros_Verm'!$D$37*'4.Parâmetros_Verm'!$F$37*'4.Parâmetros_Verm'!$G$37*'4.Parâmetros_Verm'!$H$37*'5.Mira'!$F$20*'6.Cibernético'!$C$24*'6.Cibernético'!$D$23*'9.Simulação'!$N$16)+('7.Config'!$E$12*'4.Parâmetros_Verm'!$D$46*'4.Parâmetros_Verm'!$F$46*'4.Parâmetros_Verm'!$G$46*'4.Parâmetros_Verm'!$H$46*'5.Mira'!$F$21*'6.Cibernético'!$C$24*'6.Cibernético'!$D$23*'9.Simulação'!$O$16) -> 0.3822387
